Workbook
Name IY: #REF!
Name IY: #REF!
Name IY: #REF!
Name IY: #REF!
Name IY: #REF!
Name IY: #REF!
Name IY: #REF!
Name IY: #REF!
Name IY: #REF!

Sheet Sheet1
A1: 1 | B1: 222310001 | C1: ADRIAN FAUZAN | D1: 1
D2: 2
D3: 3
D4: 4
D5: 5
D6: 6
D7: 7
D8: 8
D9: 9
A10: 2 | B10: 222310002 | C10: AHMAD ZAKI YAMAN
A11: 2
A12: 2
A13: 2
A14: 2
A15: 2
A16: 2
A17: 2
A18: 2
A19: 3 | B19: 222310003 | C19: AMANDA ZAHRA FEBRIYANI
A20: 3
A21: 3
A22: 3
A23: 3
A24: 3
A25: 3
A26: 3
A27: 3
A28: 4 | B28: 222310004 | C28: ANGGI ISMAYANTI
A29: 4
A30: 4
A31: 4
A32: 4
A33: 4
A34: 4
A35: 4
A36: 4
A37: 5 | B37: 222310005 | C37: FAHRI ISNAINI
A38: 5
A39: 5
A40: 5
...

Sheet te
A1: NO | B1: NIS | C1: NAMA PESERTA | D1: KELAS | BC1: TEKNIK JARINGAN KOMPUTER DAN TELEKOMUNIKASI | BQ1: MAPEL KONSENTRASI KEAHLIAN | CF1: NILAI UJIAN SEKOLAH | CO1: =E2 -> 1.Pendidikan Agama Islam (PAI) | CS1: =K2 -> 2.Pendidikan Pancasila | CW1: =Q2 -> 3.Bahasa Indonesia | DA1: =W2 -> 4.Pendidikan Jasmani Olahraga dan Kesehatan | DC1: =AA2 -> 5.Sejarah | DE1: =AE2 -> 6.Seni Budaya (Seni Tari) | DG1: =AG2 -> 7.Bahasa Sunda | DI1: =AK2 -> 8.Public speaking | DM1: =AM2 -> 9.Matematika | DQ1: =AS2 -> 10.Bahasa Inggris | DU1: =AY2 -> 11.Informatika | DW1: =BA2 -> 12.Projek Ilmu Pengetahuan Alam dan Sosial | DY1: =BC2 -> 13.Dasar - dasar Program Keahlian | EA1: 14. Konsentrasi Keahlian | EE1: =BW2 -> 15.Projek Kreatif dan Kewirausahaan | EI1: 16.PKL | EJ1: =CB2 -> 17.Bahasa Jepang | EN1: NILAI IJAZAH / SKL
E2: 1.Pendidikan Agama Islam (PAI) | K2: 2.Pendidikan Pancasila | Q2: 3.Bahasa Indonesia | W2: 4.Pendidikan Jasmani Olahraga dan Kesehatan | AA2: 5.Sejarah | AE2: 6.Seni Budaya (Seni Tari) | AG2: 7.Bahasa Sunda | AK2: 8.Public speaking | AM2: 9.Matematika | AS2: 10.Bahasa Inggris | AY2: 11.Informatika | BA2: 12.Projek Ilmu Pengetahuan Alam dan Sosial | BC2: 13.Dasar - dasar Program Keahlian | BE2: 14.Teknik Dasar Memprogram | BG2: 15.Rekayasa Elektronika Digital | BI2: 16.Proses Produksi & Rekayasa Elektronika | BK2: 17.Penerapan Teknik Pemograman Digital | BM2: 18.Penerapan Sistem Radio dan Televisi | BO2: 19.Perencanaan & Instalasi Rangkaian Elektronika | BQ2: 20. Perawatan dan Perbaikan Peralatan Elektronika | BS2: KONS | BW2: 15.Projek Kreatif dan Kewirausahaan | CA2: 16.PKL | CB2: 17.Bahasa Jepang | EN2: 1.Pendidikan Agama dan Budi Pekerti | EO2: 2.Pendidikan Pancasila | EP2: 3.Bahasa Indonesia | EQ2: 4.Pendidikan Jasmani Olahraga dan Kesehatan | ER2: 5.Sejarah | ES2: 6.Seni Budaya (Seni Tari) | ET2: 7.Bahasa Sunda | EU2: 8.Public speaking | EV2: 9.Matematika | EW2: 10.Bahasa Inggris | EX2: 11.Informatika | EY2: 12.Projek Ilmu Pengetahuan Alam dan Sosial | EZ2: 13.Dasar - dasar Program Keahlian | FA2: 14.Konsentrasi Keahlian | FB2: 15.Projek Kreatif dan Kewirausahaan | FC2: 16.Praktik Kerja Lapangan | FD2: 17.Mepel Pilihan (Bahasa Jepang) | FE2: RATA-RATA
E3: ST1 | F3: ST2 | G3: ST3 | H3: ST4 | I3: ST5 | J3: ST6 | K3: ST1 | L3: ST2 | M3: ST3 | N3: ST4 | O3: ST5 | P3: ST6 | Q3: ST1 | R3: ST2 | S3: ST3 | T3: ST4 | U3: ST5 | V3: ST6 | W3: ST1 | X3: ST2 | Y3: ST3 | Z3: ST4 | AA3: ST1 | AB3: ST2 | AC3: ST3 | AD3: ST4 | AE3: ST1 | AF3: ST2 | AG3: ST1 | AH3: ST2 | AI3: ST3 | AJ3: ST4 | AK3: ST5 | AL3: ST6 | AM3: ST1 | AN3: ST2 | AO3: ST3 | AP3: ST4 | AQ3: ST5 | AR3: ST6 | AS3: ST1 | AT3: ST2 | AU3: ST3 | AV3: ST4 | AW3: ST5 | AX3: ST6 | AY3: ST1 | AZ3: ST2 | BA3: ST1 | BB3: ST2 | BC3: ST1 | BD3: ST2 | BE3: ST3 | BF3: ST4 | BG3: ST3 | BH3: ST4 | BI3: ST3 | BJ3: ST4 | BK3: ST5 | BL3: ST6 | BM3: ST5 | BN3: ST6 | BO3: ST5 | BP3: ST6 | BQ3: ST5 | BR3: ST6 | BS3: ST3 | BT3: ST4 | BU3: ST5 | BV3: ST6 | BW3: ST3 | BX3: ST4 | BY3: ST5 | BZ3: ST6 | CA3: 5 | CB3: ST3 | CC3: ST4 | CD3: ST5 | CE3: ST6 | CF3: PAI | CG3: PKN | CH3: B IND | CI3: P. SPEAKING | CJ3: MTK | CK3: B ING | CL3: B JPN | CM3: PKK | CN3: KONST | CO3: PORT | CP3: ST6 | CQ3: US | CR3: NA | CS3: PORT | CT3: ST6 | CU3: US | CV3: NA | CW3: PORT | CX3: ST6 | CY3: US | CZ3: NA | DA3: PORT | DB3: NA | DC3: PORT | DD3: NA | DE3: PORT | DF3: NA | DG3: PORT | DH3: NA | DI3: PORT | DJ3: ST6 | DK3: US | DL3: NA | DM3: PORT | DN3: ST6 | DO3: US | DP3: NA | DQ3: PORT | DR3: ST6 | DS3: US | DT3: NA | DU3: PORT | DV3: NA | DW3: PORT | DX3: NA | DY3: PORT | DZ3: NA | EA3: PORT | EB3: ST6 | EC3: US | ED3: NA | EE3: PORT | EF3: ST6 | EG3: US | EH3: NA | EI3: NA | EJ3: PORT | EK3: ST6 | EL3: US | EM3: NA | EN3: 1.Pendidikan Agama dan Budi Pekerti | EO3: 2.Pendidikan Pancasila | EP3: 3.Bahasa Indonesia | EQ3: 4.Pendidikan Jasmani Olahraga dan Kesehatan | ER3: 5.Sejarah | ES3: 6.Seni Budaya (Seni Tari) | ET3: 7.Bahasa Sunda | EU3: 8.Public speaking | EV3: 9.Matematika | EW3: 10.Bahasa Inggris | EX3: 11.Informatika | EY3: 12.Projek Ilmu Pengetahuan Alam dan Sosial | EZ3: 13.Dasar - dasar Program Keahlian | FA3: 14.Konsentrasi Keahlian | FB3: 15.Projek Kreatif dan Kewirausahaan | FC3: 16.Praktik Kerja Lapangan | FD3: 17.Mepel Pilihan (Bahasa Jepang)
EN4: 1.Pendidikan Agama dan Budi Pekerti | EO4: 2.Pendidikan Pancasila | EP4: 3.Bahasa Indonesia | EQ4: 4.Pendidikan Jasmani Olahraga dan Kesehatan | ER4: 5.Sejarah | ES4: 6.Seni Budaya (Seni Tari) | ET4: 7.Bahasa Sunda | EU4: 8.Public speaking | EV4: 9.Matematika | EW4: 10.Bahasa Inggris | EX4: 11.Informatika | EY4: 12.Projek Ilmu Pengetahuan Alam dan Sosial | EZ4: 13.Dasar - dasar Program Keahlian | FA4: 14.Konsentrasi Keahlian | FB4: 15.Projek Kreatif dan Kewirausahaan | FC4: 16.Praktik Kerja Lapangan | FD4: 17.Mepel Pilihan (Bahasa Jepang)
A5: 1 | B5: 0067243013 | C5: ADRIAN FAUZAN | D5: 12 TAV | E5: 82 | F5: 89 | G5: 86 | H5: 85 | I5: 80 | J5: 80 | K5: 80 | L5: 81 | M5: 70 | N5: 83 | O5: 88 | P5: 81 | Q5: 80 | R5: 77 | S5: 70 | T5: 72 | U5: 73 | V5: 78 | W5: 82 | X5: 83 | Y5: 80 | Z5: 83 | AA5: 75 | AB5: 78 | AC5: 73 | AD5: 75 | AE5: 83 | AF5: 83 | AG5: 83 | AH5: 85 | AI5: 70 | AJ5: 80 | AK5: 89 | AL5: 78 | AM5: 75 | AN5: 76 | AO5: 72 | AP5: 73 | AQ5: 76 | AR5: 80 | AS5: 73 | AT5: 73 | AU5: 71 | AV5: 70 | AW5: 73 | AX5: 80 | AY5: 75 | AZ5: 80 | BA5: 79 | BB5: 80 | BC5: 85 | BD5: 75 | BE5: 79 | BF5: 76 | BG5: 78 | BH5: 79 | BI5: 70 | BJ5: 83 | BK5: 76 | BL5: 80 | BM5: 80 | BN5: 80 | BO5: 78 | BP5: 80 | BQ5: 74 | BR5: 80 | BS5: =AVERAGE(BE5,BG5,BI5) -> 75.666667 | BT5: =AVERAGE(BF5,BH5,BJ5) -> 79.333333 | BU5: =AVERAGE(BK5,BM5,BO5,BQ5) -> 77 | BV5: =AVERAGE(BL5,BN5,BP5,BR5) -> 80 | BW5: 82 | BX5: 80 | BY5: 70 | BZ5: 79 | CA5: 80 | CB5: 70 | CC5: 72 | CD5: 74 | CE5: 80 | CF5: 81 | CG5: 75 | CH5: 75 | CI5: 75 | CJ5: 76 | CK5: 80 | CL5: 70 | CM5: 71 | CN5: 70 | CO5: =AVERAGE(E5:I5) -> 84.4 | CP5: =J5 -> 80 | CQ5: =CF5 -> 81 | CR5: =(CO5*4+CP5*3+CQ5*3)/10 -> 82.06 | CS5: =AVERAGE(K5:O5) -> 80.4 | CT5: =P5 -> 81 | CU5: =CG5 -> 75 | CV5: =(CS5*4+CT5*3+CU5*3)/10 -> 78.96 | CW5: =AVERAGE(Q5:U5) -> 74.4 | CX5: =V5 -> 78 | CY5: =CH5 -> 75 | CZ5: =(CW5*4+CX5*3+CY5*3)/10 -> 75.66 | DA5: =AVERAGE(W5:Z5) -> 82 | DB5: =DA5 -> 82 | DC5: =AVERAGE(AA5:AD5) -> 75.25 | DD5: =DC5 -> 75.25 | DE5: =AVERAGE(AE5:AF5) -> 83 | DF5: =DE5 -> 83 | DG5: =AVERAGE(AG5:AJ5) -> 79.5 | DH5: =DG5 -> 79.5 | DI5: =AK5 -> 89 | DJ5: =AL5 -> 78 | DK5: =CI5 -> 75 | DL5: =(DI5*4+DJ5*3+DK5*3)/10 -> 81.5 | DM5: =AVERAGE(AM5:AQ5) -> 74.4 | DN5: =AR5 -> 80 | DO5: =CJ5 -> 76 | DP5: =(DM5*4+DN5*3+DO5*3)/10 -> 76.56 | DQ5: =AVERAGE(AS5:AW5) -> 72 | DR5: =AX5 -> 80 | DS5: =CK5 -> 80 | DT5: =(DQ5*4+DR5*3+DS5*3)/10 -> 76.8 | DU5: =AVERAGE(AY5:AZ5) -> 77.5 | DV5: =DU5 -> 77.5 | DW5: =AVERAGE(BA5:BB5) -> 79.5 | DX5: =DW5 -> 79.5 | DY5: =AVERAGE(BC5:BD5) -> 80 | DZ5: =DY5 -> 80 | EA5: =AVERAGE(BS5:BU5) -> 77.333333 | EB5: =BV5 -> 80 | EC5: =CN5 -> 70 | ED5: =(EA5*4+EB5*3+EC5*3)/10 -> 75.933333 | EE5: =AVERAGE(BW5:BY5) -> 77.333333 | EF5: =BZ5 -> 79 | EG5: =CM5 -> 71 | EH5: =(EE5*4+EF5*3+EG5*3)/10 -> 75.933333 | EI5: =CA5 -> 80 | EJ5: =AVERAGE(CB5:CD5) -> 72 | EK5: =CE5 -> 80 | EL5: =CL5 -> 70 | EM5: =(EJ5*4+EK5*3+EL5*3)/10 -> 73.8 | EN5: =CR5 -> 82.06 | EO5: =CV5 -> 78.96 | EP5: =CZ5 -> 75.66 | EQ5: =DB5 -> 82 | ER5: =DD5 -> 75.25 | ES5: =DF5 -> 83 | ET5: =DH5 -> 79.5 | EU5: =DL5 -> 81.5 | EV5: =DP5 -> 76.56 | EW5: =DT5 -> 76.8 | EX5: =DV5 -> 77.5 | EY5: =DX5 -> 79.5 | EZ5: =DZ5 -> 80 | FA5: =ED5 -> 75.933333 | FB5: =EH5 -> 75.933333 | FC5: =EI5 -> 80 | FD5: =EM5 -> 73.8 | FE5: =AVERAGE(EN5:FD5) -> 78.468039
A6: 2 | B6: 0062623676 | C6: AHMAD ZAKI YAMAN | D6: 12 TAV | E6: 82 | F6: 88 | G6: 87 | H6: 85 | I6: 84 | J6: 76 | K6: 80 | L6: 81 | M6: 70 | N6: 83 | O6: 88 | P6: 78 | Q6: 80 | R6: 77 | S6: 70 | T6: 73 | U6: 75 | V6: 78 | W6: 80 | X6: 83 | Y6: 80 | Z6: 83 | AA6: 75 | AB6: 78 | AC6: 80 | AD6: 80 | AE6: 83 | AF6: 83 | AG6: 83 | AH6: 84 | AI6: 70 | AJ6: 80 | AK6: 80 | AL6: 78 | AM6: 73 | AN6: 74 | AO6: 73 | AP6: 74 | AQ6: 75 | AR6: 77 | AS6: 72 | AT6: 74 | AU6: 72 | AV6: 70 | AW6: 77 | AX6: 77 | AY6: 74 | AZ6: 79 | BA6: 78 | BB6: 81 | BC6: 90 | BD6: 77 | BE6: 77 | BF6: 73 | BG6: 77 | BH6: 78 | BI6: 70 | BJ6: 83 | BK6: 75 | BL6: 78 | BM6: 80 | BN6: 78 | BO6: 78 | BP6: 78 | BQ6: 83 | BR6: 78 | BS6: =AVERAGE(BE6,BG6,BI6) -> 74.666667 | BT6: =AVERAGE(BF6,BH6,BJ6) -> 78 | BU6: =AVERAGE(BK6,BM6,BO6,BQ6) -> 79 | BV6: =AVERAGE(BL6,BN6,BP6,BR6) -> 78 | BW6: 82 | BX6: 80 | BY6: 70 | BZ6: 79 | CA6: 78 | CB6: 72 | CC6: 74 | CD6: 74 | CE6: 77 | CF6: 84 | CG6: 75 | CH6: 75 | CI6: 70 | CJ6: 76 | CK6: 80 | CL6: 72 | CM6: 73 | CN6: 70 | CO6: =AVERAGE(E6:I6) -> 85.2 | CP6: =J6 -> 76 | CQ6: =CF6 -> 84 | CR6: =(CO6*4+CP6*3+CQ6*3)/10 -> 82.08 | CS6: =AVERAGE(K6:O6) -> 80.4 | CT6: =P6 -> 78 | CU6: =CG6 -> 75 | CV6: =(CS6*4+CT6*3+CU6*3)/10 -> 78.06 | CW6: =AVERAGE(Q6:U6) -> 75 | CX6: =V6 -> 78 | CY6: =CH6 -> 75 | CZ6: =(CW6*4+CX6*3+CY6*3)/10 -> 75.9 | DA6: =AVERAGE(W6:Z6) -> 81.5 | DB6: =DA6 -> 81.5 | DC6: =AVERAGE(AA6:AD6) -> 78.25 | DD6: =DC6 -> 78.25 | DE6: =AVERAGE(AE6:AF6) -> 83 | DF6: =DE6 -> 83 | DG6: =AVERAGE(AG6:AJ6) -> 79.25 | DH6: =DG6 -> 79.25 | DI6: =AK6 -> 80 | DJ6: =AL6 -> 78 | DK6: =CI6 -> 70 | DL6: =(DI6*4+DJ6*3+DK6*3)/10 -> 76.4 | DM6: =AVERAGE(AM6:AQ6) -> 73.8 | DN6: =AR6 -> 77 | DO6: =CJ6 -> 76 | DP6: =(DM6*4+DN6*3+DO6*3)/10 -> 75.42 | DQ6: =AVERAGE(AS6:AW6) -> 73 | DR6: =AX6 -> 77 | DS6: =CK6 -> 80 | DT6: =(DQ6*4+DR6*3+DS6*3)/10 -> 76.3 | DU6: =AVERAGE(AY6:AZ6) -> 76.5 | DV6: =DU6 -> 76.5 | DW6: =AVERAGE(BA6:BB6) -> 79.5 | DX6: =DW6 -> 79.5 | DY6: =AVERAGE(BC6:BD6) -> 83.5 | DZ6: =DY6 -> 83.5 | EA6: =AVERAGE(BS6:BU6) -> 77.222222 | EB6: =BV6 -> 78 | EC6: =CN6 -> 70 | ED6: =(EA6*4+EB6*3+EC6*3)/10 -> 75.288889 | EE6: =AVERAGE(BW6:BY6) -> 77.333333 | EF6: =BZ6 -> 79 | EG6: =CM6 -> 73 | EH6: =(EE6*4+EF6*3+EG6*3)/10 -> 76.533333 | EI6: =CA6 -> 78 | EJ6: =AVERAGE(CB6:CD6) -> 73.333333 | EK6: =CE6 -> 77 | EL6: =CL6 -> 72 | EM6: =(EJ6*4+EK6*3+EL6*3)/10 -> 74.033333 | EN6: =CR6 -> 82.08 | EO6: =CV6 -> 78.06 | EP6: =CZ6 -> 75.9 | EQ6: =DB6 -> 81.5 | ER6: =DD6 -> 78.25 | ES6: =DF6 -> 83 | ET6: =DH6 -> 79.25 | EU6: =DL6 -> 76.4 | EV6: =DP6 -> 75.42 | EW6: =DT6 -> 76.3 | EX6: =DV6 -> 76.5 | EY6: =DX6 -> 79.5 | EZ6: =DZ6 -> 83.5 | FA6: =ED6 -> 75.288889 | FB6: =EH6 -> 76.533333 | FC6: =EI6 -> 78 | FD6: =EM6 -> 74.033333 | FE6: =AVERAGE(EN6:FD6) -> 78.206797
A7: 3 | B7: 0078712500 | C7: AMANDA ZAHRA FEBRIYANI | D7: 12 TAV | E7: 82 | F7: 87 | G7: 86 | H7: 85 | I7: 84 | J7: 86 | K7: 81 | L7: 83 | M7: 83 | N7: 88 | O7: 93 | P7: 95 | Q7: 85 | R7: 80 | S7: 89 | T7: 87 | U7: 81 | V7: 86 | W7: 82 | X7: 85 | Y7: 83 | Z7: 84 | AA7: 80 | AB7: 88 | AC7: 85 | AD7: 86 | AE7: 85 | AF7: 83 | AG7: 85 | AH7: 85 | AI7: 72 | AJ7: 81 | AK7: 84 | AL7: 86 | AM7: 75 | AN7: 77 | AO7: 75 | AP7: 76 | AQ7: 82 | AR7: 91 | AS7: 74 | AT7: 79 | AU7: 82 | AV7: 74 | AW7: 85 | AX7: 91 | AY7: 77 | AZ7: 81 | BA7: 83 | BB7: 82 | BC7: 80 | BD7: 80 | BE7: 81 | BF7: 78 | BG7: 82 | BH7: 81 | BI7: 77 | BJ7: 85 | BK7: 80 | BL7: 90 | BM7: 80 | BN7: 90 | BO7: 86 | BP7: 90 | BQ7: 85 | BR7: 90 | BS7: =AVERAGE(BE7,BG7,BI7) -> 80 | BT7: =AVERAGE(BF7,BH7,BJ7) -> 81.333333 | BU7: =AVERAGE(BK7,BM7,BO7,BQ7) -> 82.75 | BV7: =AVERAGE(BL7,BN7,BP7,BR7) -> 90 | BW7: 84 | BX7: 81 | BY7: 86 | BZ7: 90 | CA7: 90 | CB7: 79 | CC7: 92 | CD7: 89 | CE7: 91 | CF7: 86 | CG7: 85 | CH7: 82 | CI7: 95 | CJ7: 83 | CK7: 85 | CL7: 84 | CM7: 87 | CN7: 82 | CO7: =AVERAGE(E7:I7) -> 84.8 | CP7: =J7 -> 86 | CQ7: =CF7 -> 86 | CR7: =(CO7*4+CP7*3+CQ7*3)/10 -> 85.52 | CS7: =AVERAGE(K7:O7) -> 85.6 | CT7: =P7 -> 95 | CU7: =CG7 -> 85 | CV7: =(CS7*4+CT7*3+CU7*3)/10 -> 88.24 | CW7: =AVERAGE(Q7:U7) -> 84.4 | CX7: =V7 -> 86 | CY7: =CH7 -> 82 | CZ7: =(CW7*4+CX7*3+CY7*3)/10 -> 84.16 | DA7: =AVERAGE(W7:Z7) -> 83.5 | DB7: =DA7 -> 83.5 | DC7: =AVERAGE(AA7:AD7) -> 84.75 | DD7: =DC7 -> 84.75 | DE7: =AVERAGE(AE7:AF7) -> 84 | DF7: =DE7 -> 84 | DG7: =AVERAGE(AG7:AJ7) -> 80.75 | DH7: =DG7 -> 80.75 | DI7: =AK7 -> 84 | DJ7: =AL7 -> 86 | DK7: =CI7 -> 95 | DL7: =(DI7*4+DJ7*3+DK7*3)/10 -> 87.9 | DM7: =AVERAGE(AM7:AQ7) -> 77 | DN7: =AR7 -> 91 | DO7: =CJ7 -> 83 | DP7: =(DM7*4+DN7*3+DO7*3)/10 -> 83 | DQ7: =AVERAGE(AS7:AW7) -> 78.8 | DR7: =AX7 -> 91 | DS7: =CK7 -> 85 | DT7: =(DQ7*4+DR7*3+DS7*3)/10 -> 84.32 | DU7: =AVERAGE(AY7:AZ7) -> 79 | DV7: =DU7 -> 79 | DW7: =AVERAGE(BA7:BB7) -> 82.5 | DX7: =DW7 -> 82.5 | DY7: =AVERAGE(BC7:BD7) -> 80 | DZ7: =DY7 -> 80 | EA7: =AVERAGE(BS7:BU7) -> 81.361111 | EB7: =BV7 -> 90 | EC7: =CN7 -> 82 | ED7: =(EA7*4+EB7*3+EC7*3)/10 -> 84.144444 | EE7: =AVERAGE(BW7:BY7) -> 83.666667 | EF7: =BZ7 -> 90 | EG7: =CM7 -> 87 | EH7: =(EE7*4+EF7*3+EG7*3)/10 -> 86.566667 | EI7: =CA7 -> 90 | EJ7: =AVERAGE(CB7:CD7) -> 86.666667 | EK7: =CE7 -> 91 | EL7: =CL7 -> 84 | EM7: =(EJ7*4+EK7*3+EL7*3)/10 -> 87.166667 | EN7: =CR7 -> 85.52 | EO7: =CV7 -> 88.24 | EP7: =CZ7 -> 84.16 | EQ7: =DB7 -> 83.5 | ER7: =DD7 -> 84.75 | ES7: =DF7 -> 84 | ET7: =DH7 -> 80.75 | EU7: =DL7 -> 87.9 | EV7: =DP7 -> 83 | EW7: =DT7 -> 84.32 | EX7: =DV7 -> 79 | EY7: =DX7 -> 82.5 | EZ7: =DZ7 -> 80 | FA7: =ED7 -> 84.144444 | FB7: =EH7 -> 86.566667 | FC7: =EI7 -> 90 | FD7: =EM7 -> 87.166667 | FE7: =AVERAGE(EN7:FD7) -> 84.442222
A8: 4 | B8: 0076916900 | C8: ANGGI ISMAYANTI | D8: 12 TAV | E8: 86 | F8: 90 | G8: 88 | H8: 87 | I8: 90 | J8: 75 | K8: 83 | L8: 81 | M8: 82 | N8: 89 | O8: 89 | P8: 70 | Q8: 87 | R8: 80 | S8: 80 | T8: 80 | U8: 85 | V8: 79 | W8: 81 | X8: 85 | Y8: 83 | Z8: 84 | AA8: 77 | AB8: 88 | AC8: 85 | AD8: 86 | AE8: 84 | AF8: 85 | AG8: 84 | AH8: 85 | AI8: 71 | AJ8: 81 | AK8: 85 | AL8: 79 | AM8: 77 | AN8: 79 | AO8: 78 | AP8: 79 | AQ8: 82 | AR8: 72 | AS8: 77 | AT8: 79 | AU8: 73 | AV8: 72 | AW8: 82 | AX8: 72 | AY8: 80 | AZ8: 82 | BA8: 84 | BB8: 85 | BC8: 83 | BD8: 81 | BE8: 82 | BF8: 75 | BG8: 83 | BH8: 81 | BI8: 80 | BJ8: 84 | BK8: 81 | BL8: 75 | BM8: 80 | BN8: 75 | BO8: 85 | BP8: 75 | BQ8: 84 | BR8: 75 | BS8: =AVERAGE(BE8,BG8,BI8) -> 81.666667 | BT8: =AVERAGE(BF8,BH8,BJ8) -> 80 | BU8: =AVERAGE(BK8,BM8,BO8,BQ8) -> 82.5 | BV8: =AVERAGE(BL8,BN8,BP8,BR8) -> 75 | BW8: 84 | BX8: 81 | BY8: 86 | BZ8: 79 | CA8: 75 | CB8: 78 | CC8: 91 | CD8: 74 | CE8: 72 | CF8: 89 | CG8: 85 | CH8: 85 | CI8: 77 | CJ8: 83 | CK8: 82 | CL8: 84 | CM8: 90 | CN8: 72 | CO8: =AVERAGE(E8:I8) -> 88.2 | CP8: =J8 -> 75 | CQ8: =CF8 -> 89 | CR8: =(CO8*4+CP8*3+CQ8*3)/10 -> 84.48 | CS8: =AVERAGE(K8:O8) -> 84.8 | CT8: =P8 -> 70 | CU8: =CG8 -> 85 | CV8: =(CS8*4+CT8*3+CU8*3)/10 -> 80.42 | CW8: =AVERAGE(Q8:U8) -> 82.4 | CX8: =V8 -> 79 | CY8: =CH8 -> 85 | CZ8: =(CW8*4+CX8*3+CY8*3)/10 -> 82.16 | DA8: =AVERAGE(W8:Z8) -> 83.25 | DB8: =DA8 -> 83.25 | DC8: =AVERAGE(AA8:AD8) -> 84 | DD8: =DC8 -> 84 | DE8: =AVERAGE(AE8:AF8) -> 84.5 | DF8: =DE8 -> 84.5 | DG8: =AVERAGE(AG8:AJ8) -> 80.25 | DH8: =DG8 -> 80.25 | DI8: =AK8 -> 85 | DJ8: =AL8 -> 79 | DK8: =CI8 -> 77 | DL8: =(DI8*4+DJ8*3+DK8*3)/10 -> 80.8 | DM8: =AVERAGE(AM8:AQ8) -> 79 | DN8: =AR8 -> 72 | DO8: =CJ8 -> 83 | DP8: =(DM8*4+DN8*3+DO8*3)/10 -> 78.1 | DQ8: =AVERAGE(AS8:AW8) -> 76.6 | DR8: =AX8 -> 72 | DS8: =CK8 -> 82 | DT8: =(DQ8*4+DR8*3+DS8*3)/10 -> 76.84 | DU8: =AVERAGE(AY8:AZ8) -> 81 | DV8: =DU8 -> 81 | DW8: =AVERAGE(BA8:BB8) -> 84.5 | DX8: =DW8 -> 84.5 | DY8: =AVERAGE(BC8:BD8) -> 82 | DZ8: =DY8 -> 82 | EA8: =AVERAGE(BS8:BU8) -> 81.388889 | EB8: =BV8 -> 75 | EC8: =CN8 -> 72 | ED8: =(EA8*4+EB8*3+EC8*3)/10 -> 76.655556 | EE8: =AVERAGE(BW8:BY8) -> 83.666667 | EF8: =BZ8 -> 79 | EG8: =CM8 -> 90 | EH8: =(EE8*4+EF8*3+EG8*3)/10 -> 84.166667 | EI8: =CA8 -> 75 | EJ8: =AVERAGE(CB8:CD8) -> 81 | EK8: =CE8 -> 72 | EL8: =CL8 -> 84 | EM8: =(EJ8*4+EK8*3+EL8*3)/10 -> 79.2 | EN8: =CR8 -> 84.48 | EO8: =CV8 -> 80.42 | EP8: =CZ8 -> 82.16 | EQ8: =DB8 -> 83.25 | ER8: =DD8 -> 84 | ES8: =DF8 -> 84.5 | ET8: =DH8 -> 80.25 | EU8: =DL8 -> 80.8 | EV8: =DP8 -> 78.1 | EW8: =DT8 -> 76.84 | EX8: =DV8 -> 81 | EY8: =DX8 -> 84.5 | EZ8: =DZ8 -> 82 | FA8: =ED8 -> 76.655556 | FB8: =EH8 -> 84.166667 | FC8: =EI8 -> 75 | FD8: =EM8 -> 79.2 | FE8: =AVERAGE(EN8:FD8) -> 81.018954
A9: 5 | B9: 0073506435 | C9: FAHRI ISNAINI | D9: 12 TAV | E9: 86 | F9: 89 | G9: 86 | H9: 85 | I9: 86 | J9: 74 | K9: 80 | L9: 82 | M9: 88 | N9: 90 | O9: 93 | P9: 85 | Q9: 80 | R9: 77 | S9: 76 | T9: 79 | U9: 77 | V9: 75 | W9: 81 | X9: 84 | Y9: 83 | Z9: 84 | AA9: 79 | AB9: 80 | AC9: 81 | AD9: 81 | AE9: 82 | AF9: 83 | AG9: 82 | AH9: 83 | AI9: 70 | AJ9: 82 | AK9: 80 | AL9: 75 | AM9: 74 | AN9: 75 | AO9: 74 | AP9: 75 | AQ9: 79 | AR9: 74 | AS9: 73 | AT9: 76 | AU9: 79 | AV9: 70 | AW9: 83 | AX9: 74 | AY9: 75 | AZ9: 79 | BA9: 80 | BB9: 84 | BC9: 77 | BD9: 83 | BE9: 79 | BF9: 81 | BG9: 83 | BH9: 80 | BI9: 79 | BJ9: 84 | BK9: 81 | BL9: 76 | BM9: 80 | BN9: 76 | BO9: 78 | BP9: 76 | BQ9: 83 | BR9: 76 | BS9: =AVERAGE(BE9,BG9,BI9) -> 80.333333 | BT9: =AVERAGE(BF9,BH9,BJ9) -> 81.666667 | BU9: =AVERAGE(BK9,BM9,BO9,BQ9) -> 80.5 | BV9: =AVERAGE(BL9,BN9,BP9,BR9) -> 76 | BW9: 84 | BX9: 80 | BY9: 85 | BZ9: 74 | CA9: 76 | CB9: 74 | CC9: 85 | CD9: 75 | CE9: 74 | CF9: 86 | CG9: 82 | CH9: 75 | CI9: 90 | CJ9: 80 | CK9: 80 | CL9: 88 | CM9: 80 | CN9: 75 | CO9: =AVERAGE(E9:I9) -> 86.4 | CP9: =J9 -> 74 | CQ9: =CF9 -> 86 | CR9: =(CO9*4+CP9*3+CQ9*3)/10 -> 82.56 | CS9: =AVERAGE(K9:O9) -> 86.6 | CT9: =P9 -> 85 | CU9: =CG9 -> 82 | CV9: =(CS9*4+CT9*3+CU9*3)/10 -> 84.74 | CW9: =AVERAGE(Q9:U9) -> 77.8 | CX9: =V9 -> 75 | CY9: =CH9 -> 75 | CZ9: =(CW9*4+CX9*3+CY9*3)/10 -> 76.12 | DA9: =AVERAGE(W9:Z9) -> 83 | DB9: =DA9 -> 83 | DC9: =AVERAGE(AA9:AD9) -> 80.25 | DD9: =DC9 -> 80.25 | DE9: =AVERAGE(AE9:AF9) -> 82.5 | DF9: =DE9 -> 82.5 | DG9: =AVERAGE(AG9:AJ9) -> 79.25 | DH9: =DG9 -> 79.25 | DI9: =AK9 -> 80 | DJ9: =AL9 -> 75 | DK9: =CI9 -> 90 | DL9: =(DI9*4+DJ9*3+DK9*3)/10 -> 81.5 | DM9: =AVERAGE(AM9:AQ9) -> 75.4 | DN9: =AR9 -> 74 | DO9: =CJ9 -> 80 | DP9: =(DM9*4+DN9*3+DO9*3)/10 -> 76.36 | DQ9: =AVERAGE(AS9:AW9) -> 76.2 | DR9: =AX9 -> 74 | DS9: =CK9 -> 80 | DT9: =(DQ9*4+DR9*3+DS9*3)/10 -> 76.68 | DU9: =AVERAGE(AY9:AZ9) -> 77 | DV9: =DU9 -> 77 | DW9: =AVERAGE(BA9:BB9) -> 82 | DX9: =DW9 -> 82 | DY9: =AVERAGE(BC9:BD9) -> 80 | DZ9: =DY9 -> 80 | EA9: =AVERAGE(BS9:BU9) -> 80.833333 | EB9: =BV9 -> 76 | EC9: =CN9 -> 75 | ED9: =(EA9*4+EB9*3+EC9*3)/10 -> 77.633333 | EE9: =AVERAGE(BW9:BY9) -> 83 | EF9: =BZ9 -> 74 | EG9: =CM9 -> 80 | EH9: =(EE9*4+EF9*3+EG9*3)/10 -> 79.4 | EI9: =CA9 -> 76 | EJ9: =AVERAGE(CB9:CD9) -> 78 | EK9: =CE9 -> 74 | EL9: =CL9 -> 88 | EM9: =(EJ9*4+EK9*3+EL9*3)/10 -> 79.8 | EN9: =CR9 -> 82.56 | EO9: =CV9 -> 84.74 | EP9: =CZ9 -> 76.12 | EQ9: =DB9 -> 83 | ER9: =DD9 -> 80.25 | ES9: =DF9 -> 82.5 | ET9: =DH9 -> 79.25 | EU9: =DL9 -> 81.5 | EV9: =DP9 -> 76.36 | EW9: =DT9 -> 76.68 | EX9: =DV9 -> 77 | EY9: =DX9 -> 82 | EZ9: =DZ9 -> 80 | FA9: =ED9 -> 77.633333 | FB9: =EH9 -> 79.4 | FC9: =EI9 -> 76 | FD9: =EM9 -> 79.8 | FE9: =AVERAGE(EN9:FD9) -> 79.693725
A10: 6 | B10: 0071025955 | C10: INDRIYANI | D10: 12 TAV | E10: 84 | F10: 89 | G10: 87 | H10: 87 | I10: 83 | J10: 89 | K10: 87 | L10: 83 | M10: 85 | N10: 92 | O10: 94 | P10: 92 | Q10: 85 | R10: 81 | S10: 78 | T10: 86 | U10: 79 | V10: 86 | W10: 83 | X10: 85 | Y10: 83 | Z10: 84 | AA10: 82 | AB10: 80 | AC10: 85 | AD10: 85 | AE10: 84 | AF10: 84 | AG10: 84 | AH10: 85 | AI10: 70 | AJ10: 81 | AK10: 86 | AL10: 86 | AM10: 79 | AN10: 81 | AO10: 88 | AP10: 84 | AQ10: 84 | AR10: 90 | AS10: 73 | AT10: 77 | AU10: 76 | AV10: 71 | AW10: 83 | AX10: 90 | AY10: 80 | AZ10: 82 | BA10: 83 | BB10: 83 | BC10: 91 | BD10: 85 | BE10: 80 | BF10: 79 | BG10: 81 | BH10: 81 | BI10: 82 | BJ10: 85 | BK10: 79 | BL10: 89 | BM10: 80 | BN10: 89 | BO10: 87 | BP10: 89 | BQ10: 85 | BR10: 89 | BS10: =AVERAGE(BE10,BG10,BI10) -> 81 | BT10: =AVERAGE(BF10,BH10,BJ10) -> 81.666667 | BU10: =AVERAGE(BK10,BM10,BO10,BQ10) -> 82.75 | BV10: =AVERAGE(BL10,BN10,BP10,BR10) -> 89 | BW10: 85 | BX10: 81 | BY10: 86 | BZ10: 89 | CA10: 89 | CB10: 78 | CC10: 90 | CD10: 85 | CE10: 90 | CF10: 84 | CG10: 85 | CH10: 80 | CI10: 82 | CJ10: 84 | CK10: 83 | CL10: 84 | CM10: 90 | CN10: 80 | CO10: =AVERAGE(E10:I10) -> 86 | CP10: =J10 -> 89 | CQ10: =CF10 -> 84 | CR10: =(CO10*4+CP10*3+CQ10*3)/10 -> 86.3 | CS10: =AVERAGE(K10:O10) -> 88.2 | CT10: =P10 -> 92 | CU10: =CG10 -> 85 | CV10: =(CS10*4+CT10*3+CU10*3)/10 -> 88.38 | CW10: =AVERAGE(Q10:U10) -> 81.8 | CX10: =V10 -> 86 | CY10: =CH10 -> 80 | CZ10: =(CW10*4+CX10*3+CY10*3)/10 -> 82.52 | DA10: =AVERAGE(W10:Z10) -> 83.75 | DB10: =DA10 -> 83.75 | DC10: =AVERAGE(AA10:AD10) -> 83 | DD10: =DC10 -> 83 | DE10: =AVERAGE(AE10:AF10) -> 84 | DF10: =DE10 -> 84 | DG10: =AVERAGE(AG10:AJ10) -> 80 | DH10: =DG10 -> 80 | DI10: =AK10 -> 86 | DJ10: =AL10 -> 86 | DK10: =CI10 -> 82 | DL10: =(DI10*4+DJ10*3+DK10*3)/10 -> 84.8 | DM10: =AVERAGE(AM10:AQ10) -> 83.2 | DN10: =AR10 -> 90 | DO10: =CJ10 -> 84 | DP10: =(DM10*4+DN10*3+DO10*3)/10 -> 85.48 | DQ10: =AVERAGE(AS10:AW10) -> 76 | DR10: =AX10 -> 90 | DS10: =CK10 -> 83 | DT10: =(DQ10*4+DR10*3+DS10*3)/10 -> 82.3 | DU10: =AVERAGE(AY10:AZ10) -> 81 | DV10: =DU10 -> 81 | DW10: =AVERAGE(BA10:BB10) -> 83 | DX10: =DW10 -> 83 | DY10: =AVERAGE(BC10:BD10) -> 88 | DZ10: =DY10 -> 88 | EA10: =AVERAGE(BS10:BU10) -> 81.805556 | EB10: =BV10 -> 89 | EC10: =CN10 -> 80 | ED10: =(EA10*4+EB10*3+EC10*3)/10 -> 83.422222 | EE10: =AVERAGE(BW10:BY10) -> 84 | EF10: =BZ10 -> 89 | EG10: =CM10 -> 90 | EH10: =(EE10*4+EF10*3+EG10*3)/10 -> 87.3 | EI10: =CA10 -> 89 | EJ10: =AVERAGE(CB10:CD10) -> 84.333333 | EK10: =CE10 -> 90 | EL10: =CL10 -> 84 | EM10: =(EJ10*4+EK10*3+EL10*3)/10 -> 85.933333 | EN10: =CR10 -> 86.3 | EO10: =CV10 -> 88.38 | EP10: =CZ10 -> 82.52 | EQ10: =DB10 -> 83.75 | ER10: =DD10 -> 83 | ES10: =DF10 -> 84 | ET10: =DH10 -> 80 | EU10: =DL10 -> 84.8 | EV10: =DP10 -> 85.48 | EW10: =DT10 -> 82.3 | EX10: =DV10 -> 81 | EY10: =DX10 -> 83 | EZ10: =DZ10 -> 88 | FA10: =ED10 -> 83.422222 | FB10: =EH10 -> 87.3 | FC10: =EI10 -> 89 | FD10: =EM10 -> 85.933333 | FE10: =AVERAGE(EN10:FD10) -> 84.59915
A11: 7 | B11: 0076911645 | C11: JERICHO AMAZIA AWULLE | D11: 12 TAV | E11: 80 | F11: 87 | G11: 88 | H11: 87 | I11: 85 | J11: 75 | K11: 80 | L11: 81 | M11: 92 | N11: 88 | O11: 93 | P11: 75 | Q11: 78 | R11: 78 | S11: 70 | T11: 71 | U11: 73 | V11: 75 | W11: 85 | X11: 86 | Y11: 84 | Z11: 85 | AA11: 78 | AB11: 80 | AC11: 83 | AD11: 84 | AE11: 80 | AF11: 79 | AG11: 80 | AH11: 81 | AI11: 71 | AJ11: 81 | AK11: 80 | AL11: 75 | AM11: 74 | AN11: 76 | AO11: 73 | AP11: 74 | AQ11: 72 | AR11: 75 | AS11: 71 | AT11: 73 | AU11: 70 | AV11: 70 | AW11: 73 | AX11: 75 | AY11: 77 | AZ11: 78 | BA11: 78 | BB11: 81 | BC11: 77 | BD11: 77 | BE11: 80 | BF11: 74 | BG11: 79 | BH11: 80 | BI11: 82 | BJ11: 85 | BK11: 77 | BL11: 75 | BM11: 80 | BN11: 75 | BO11: 84 | BP11: 75 | BQ11: 84 | BR11: 75 | BS11: =AVERAGE(BE11,BG11,BI11) -> 80.333333 | BT11: =AVERAGE(BF11,BH11,BJ11) -> 79.666667 | BU11: =AVERAGE(BK11,BM11,BO11,BQ11) -> 81.25 | BV11: =AVERAGE(BL11,BN11,BP11,BR11) -> 75 | BW11: 84 | BX11: 80 | BY11: 70 | BZ11: 75 | CA11: 75 | CB11: 72 | CC11: 77 | CD11: 73 | CE11: 75 | CF11: 86 | CG11: 70 | CH11: 70 | CI11: 70 | CJ11: 75 | CK11: 80 | CL11: 86 | CM11: 73 | CN11: 70 | CO11: =AVERAGE(E11:I11) -> 85.4 | CP11: =J11 -> 75 | CQ11: =CF11 -> 86 | CR11: =(CO11*4+CP11*3+CQ11*3)/10 -> 82.46 | CS11: =AVERAGE(K11:O11) -> 86.8 | CT11: =P11 -> 75 | CU11: =CG11 -> 70 | CV11: =(CS11*4+CT11*3+CU11*3)/10 -> 78.22 | CW11: =AVERAGE(Q11:U11) -> 74 | CX11: =V11 -> 75 | CY11: =CH11 -> 70 | CZ11: =(CW11*4+CX11*3+CY11*3)/10 -> 73.1 | DA11: =AVERAGE(W11:Z11) -> 85 | DB11: =DA11 -> 85 | DC11: =AVERAGE(AA11:AD11) -> 81.25 | DD11: =DC11 -> 81.25 | DE11: =AVERAGE(AE11:AF11) -> 79.5 | DF11: =DE11 -> 79.5 | DG11: =AVERAGE(AG11:AJ11) -> 78.25 | DH11: =DG11 -> 78.25 | DI11: =AK11 -> 80 | DJ11: =AL11 -> 75 | DK11: =CI11 -> 70 | DL11: =(DI11*4+DJ11*3+DK11*3)/10 -> 75.5 | DM11: =AVERAGE(AM11:AQ11) -> 73.8 | DN11: =AR11 -> 75 | DO11: =CJ11 -> 75 | DP11: =(DM11*4+DN11*3+DO11*3)/10 -> 74.52 | DQ11: =AVERAGE(AS11:AW11) -> 71.4 | DR11: =AX11 -> 75 | DS11: =CK11 -> 80 | DT11: =(DQ11*4+DR11*3+DS11*3)/10 -> 75.06 | DU11: =AVERAGE(AY11:AZ11) -> 77.5 | DV11: =DU11 -> 77.5 | DW11: =AVERAGE(BA11:BB11) -> 79.5 | DX11: =DW11 -> 79.5 | DY11: =AVERAGE(BC11:BD11) -> 77 | DZ11: =DY11 -> 77 | EA11: =AVERAGE(BS11:BU11) -> 80.416667 | EB11: =BV11 -> 75 | EC11: =CN11 -> 70 | ED11: =(EA11*4+EB11*3+EC11*3)/10 -> 75.666667 | EE11: =AVERAGE(BW11:BY11) -> 78 | EF11: =BZ11 -> 75 | EG11: =CM11 -> 73 | EH11: =(EE11*4+EF11*3+EG11*3)/10 -> 75.6 | EI11: =CA11 -> 75 | EJ11: =AVERAGE(CB11:CD11) -> 74 | EK11: =CE11 -> 75 | EL11: =CL11 -> 86 | EM11: =(EJ11*4+EK11*3+EL11*3)/10 -> 77.9 | EN11: =CR11 -> 82.46 | EO11: =CV11 -> 78.22 | EP11: =CZ11 -> 73.1 | EQ11: =DB11 -> 85 | ER11: =DD11 -> 81.25 | ES11: =DF11 -> 79.5 | ET11: =DH11 -> 78.25 | EU11: =DL11 -> 75.5 | EV11: =DP11 -> 74.52 | EW11: =DT11 -> 75.06 | EX11: =DV11 -> 77.5 | EY11: =DX11 -> 79.5 | EZ11: =DZ11 -> 77 | FA11: =ED11 -> 75.666667 | FB11: =EH11 -> 75.6 | FC11: =EI11 -> 75 | FD11: =EM11 -> 77.9 | FE11: =AVERAGE(EN11:FD11) -> 77.707451
A12: 8 | B12: 0078635840 | C12: KHALIF HONEST TAWADLU | D12: 12 TAV | E12: 82 | F12: 87 | G12: 84 | H12: 83 | I12: 85 | J12: 90 | K12: 80 | L12: 80 | M12: 93 | N12: 95 | O12: 95 | P12: 93 | Q12: 78 | R12: 78 | S12: 70 | T12: 73 | U12: 73 | V12: 89 | W12: 85 | X12: 85 | Y12: 84 | Z12: 85 | AA12: 80 | AB12: 82 | AC12: 83 | AD12: 83 | AE12: 81 | AF12: 80 | AG12: 81 | AH12: 86 | AI12: 70 | AJ12: 81 | AK12: 80 | AL12: 89 | AM12: 74 | AN12: 75 | AO12: 72 | AP12: 73 | AQ12: 74 | AR12: 90 | AS12: 71 | AT12: 74 | AU12: 72 | AV12: 71 | AW12: 77 | AX12: 90 | AY12: 77 | AZ12: 79 | BA12: 78 | BB12: 81 | BC12: 77 | BD12: 80 | BE12: 79 | BF12: 77 | BG12: 81 | BH12: 79 | BI12: 70 | BJ12: 84 | BK12: 79 | BL12: 91 | BM12: 80 | BN12: 91 | BO12: 79 | BP12: 91 | BQ12: 71 | BR12: 91 | BS12: =AVERAGE(BE12,BG12,BI12) -> 76.666667 | BT12: =AVERAGE(BF12,BH12,BJ12) -> 80 | BU12: =AVERAGE(BK12,BM12,BO12,BQ12) -> 77.25 | BV12: =AVERAGE(BL12,BN12,BP12,BR12) -> 91 | BW12: 84 | BX12: 80 | BY12: 70 | BZ12: 93 | CA12: 91 | CB12: 70 | CC12: 74 | CD12: 77 | CE12: 90 | CF12: 81 | CG12: 90 | CH12: 70 | CI12: 95 | CJ12: 76 | CK12: 80 | CL12: 76 | CM12: 93 | CN12: 95 | CO12: =AVERAGE(E12:I12) -> 84.2 | CP12: =J12 -> 90 | CQ12: =CF12 -> 81 | CR12: =(CO12*4+CP12*3+CQ12*3)/10 -> 84.98 | CS12: =AVERAGE(K12:O12) -> 88.6 | CT12: =P12 -> 93 | CU12: =CG12 -> 90 | CV12: =(CS12*4+CT12*3+CU12*3)/10 -> 90.34 | CW12: =AVERAGE(Q12:U12) -> 74.4 | CX12: =V12 -> 89 | CY12: =CH12 -> 70 | CZ12: =(CW12*4+CX12*3+CY12*3)/10 -> 77.46 | DA12: =AVERAGE(W12:Z12) -> 84.75 | DB12: =DA12 -> 84.75 | DC12: =AVERAGE(AA12:AD12) -> 82 | DD12: =DC12 -> 82 | DE12: =AVERAGE(AE12:AF12) -> 80.5 | DF12: =DE12 -> 80.5 | DG12: =AVERAGE(AG12:AJ12) -> 79.5 | DH12: =DG12 -> 79.5 | DI12: =AK12 -> 80 | DJ12: =AL12 -> 89 | DK12: =CI12 -> 95 | DL12: =(DI12*4+DJ12*3+DK12*3)/10 -> 87.2 | DM12: =AVERAGE(AM12:AQ12) -> 73.6 | DN12: =AR12 -> 90 | DO12: =CJ12 -> 76 | DP12: =(DM12*4+DN12*3+DO12*3)/10 -> 79.24 | DQ12: =AVERAGE(AS12:AW12) -> 73 | DR12: =AX12 -> 90 | DS12: =CK12 -> 80 | DT12: =(DQ12*4+DR12*3+DS12*3)/10 -> 80.2 | DU12: =AVERAGE(AY12:AZ12) -> 78 | DV12: =DU12 -> 78 | DW12: =AVERAGE(BA12:BB12) -> 79.5 | DX12: =DW12 -> 79.5 | DY12: =AVERAGE(BC12:BD12) -> 78.5 | DZ12: =DY12 -> 78.5 | EA12: =AVERAGE(BS12:BU12) -> 77.972222 | EB12: =BV12 -> 91 | EC12: =CN12 -> 95 | ED12: =(EA12*4+EB12*3+EC12*3)/10 -> 86.988889 | EE12: =AVERAGE(BW12:BY12) -> 78 | EF12: =BZ12 -> 93 | EG12: =CM12 -> 93 | EH12: =(EE12*4+EF12*3+EG12*3)/10 -> 87 | EI12: =CA12 -> 91 | EJ12: =AVERAGE(CB12:CD12) -> 73.666667 | EK12: =CE12 -> 90 | EL12: =CL12 -> 76 | EM12: =(EJ12*4+EK12*3+EL12*3)/10 -> 79.266667 | EN12: =CR12 -> 84.98 | EO12: =CV12 -> 90.34 | EP12: =CZ12 -> 77.46 | EQ12: =DB12 -> 84.75 | ER12: =DD12 -> 82 | ES12: =DF12 -> 80.5 | ET12: =DH12 -> 79.5 | EU12: =DL12 -> 87.2 | EV12: =DP12 -> 79.24 | EW12: =DT12 -> 80.2 | EX12: =DV12 -> 78 | EY12: =DX12 -> 79.5 | EZ12: =DZ12 -> 78.5 | FA12: =ED12 -> 86.988889 | FB12: =EH12 -> 87 | FC12: =EI12 -> 91 | FD12: =EM12 -> 79.266667 | FE12: =AVERAGE(EN12:FD12) -> 82.730915
A13: 9 | B13: 0077294980 | C13: RAFAELINO RUFFUS SERAN | D13: 12 TAV | E13: 86 | F13: 89 | G13: 87 | H13: 87 | I13: 92 | J13: 71 | K13: 82 | L13: 87 | M13: 95 | N13: 95 | O13: 95 | P13: 85 | Q13: 90 | R13: 83 | S13: 89 | T13: 85 | U13: 87 | V13: 79 | W13: 82 | X13: 85 | Y13: 83 | Z13: 84 | AA13: 89 | AB13: 89 | AC13: 85 | AD13: 86 | AE13: 81 | AF13: 83 | AG13: 81 | AH13: 82 | AI13: 71 | AJ13: 83 | AK13: 83 | AL13: 79 | AM13: 84 | AN13: 85 | AO13: 89 | AP13: 90 | AQ13: 86 | AR13: 85 | AS13: 81 | AT13: 83 | AU13: 85 | AV13: 85 | AW13: 85 | AX13: 85 | AY13: 79 | AZ13: 80 | BA13: 88 | BB13: 90 | BC13: 90 | BD13: 87 | BE13: 82 | BF13: 83 | BG13: 84 | BH13: 82 | BI13: 84 | BJ13: 85 | BK13: 82 | BL13: 82 | BM13: 80 | BN13: 82 | BO13: 86 | BP13: 82 | BQ13: 84 | BR13: 82 | BS13: =AVERAGE(BE13,BG13,BI13) -> 83.333333 | BT13: =AVERAGE(BF13,BH13,BJ13) -> 83.333333 | BU13: =AVERAGE(BK13,BM13,BO13,BQ13) -> 83 | BV13: =AVERAGE(BL13,BN13,BP13,BR13) -> 82 | BW13: 85 | BX13: 80 | BY13: 85 | BZ13: 88 | CA13: 82 | CB13: 81 | CC13: 88 | CD13: 76 | CE13: 85 | CF13: 80 | CG13: 95 | CH13: 78 | CI13: 85 | CJ13: 87 | CK13: 85 | CL13: 89 | CM13: 85 | CN13: 90 | CO13: =AVERAGE(E13:I13) -> 88.2 | CP13: =J13 -> 71 | CQ13: =CF13 -> 80 | CR13: =(CO13*4+CP13*3+CQ13*3)/10 -> 80.58 | CS13: =AVERAGE(K13:O13) -> 90.8 | CT13: =P13 -> 85 | CU13: =CG13 -> 95 | CV13: =(CS13*4+CT13*3+CU13*3)/10 -> 90.32 | CW13: =AVERAGE(Q13:U13) -> 86.8 | CX13: =V13 -> 79 | CY13: =CH13 -> 78 | CZ13: =(CW13*4+CX13*3+CY13*3)/10 -> 81.82 | DA13: =AVERAGE(W13:Z13) -> 83.5 | DB13: =DA13 -> 83.5 | DC13: =AVERAGE(AA13:AD13) -> 87.25 | DD13: =DC13 -> 87.25 | DE13: =AVERAGE(AE13:AF13) -> 82 | DF13: =DE13 -> 82 | DG13: =AVERAGE(AG13:AJ13) -> 79.25 | DH13: =DG13 -> 79.25 | DI13: =AK13 -> 83 | DJ13: =AL13 -> 79 | DK13: =CI13 -> 85 | DL13: =(DI13*4+DJ13*3+DK13*3)/10 -> 82.4 | DM13: =AVERAGE(AM13:AQ13) -> 86.8 | DN13: =AR13 -> 85 | DO13: =CJ13 -> 87 | DP13: =(DM13*4+DN13*3+DO13*3)/10 -> 86.32 | DQ13: =AVERAGE(AS13:AW13) -> 83.8 | DR13: =AX13 -> 85 | DS13: =CK13 -> 85 | DT13: =(DQ13*4+DR13*3+DS13*3)/10 -> 84.52 | DU13: =AVERAGE(AY13:AZ13) -> 79.5 | DV13: =DU13 -> 79.5 | DW13: =AVERAGE(BA13:BB13) -> 89 | DX13: =DW13 -> 89 | DY13: =AVERAGE(BC13:BD13) -> 88.5 | DZ13: =DY13 -> 88.5 | EA13: =AVERAGE(BS13:BU13) -> 83.222222 | EB13: =BV13 -> 82 | EC13: =CN13 -> 90 | ED13: =(EA13*4+EB13*3+EC13*3)/10 -> 84.888889 | EE13: =AVERAGE(BW13:BY13) -> 83.333333 | EF13: =BZ13 -> 88 | EG13: =CM13 -> 85 | EH13: =(EE13*4+EF13*3+EG13*3)/10 -> 85.233333 | EI13: =CA13 -> 82 | EJ13: =AVERAGE(CB13:CD13) -> 81.666667 | EK13: =CE13 -> 85 | EL13: =CL13 -> 89 | EM13: =(EJ13*4+EK13*3+EL13*3)/10 -> 84.866667 | EN13: =CR13 -> 80.58 | EO13: =CV13 -> 90.32 | EP13: =CZ13 -> 81.82 | EQ13: =DB13 -> 83.5 | ER13: =DD13 -> 87.25 | ES13: =DF13 -> 82 | ET13: =DH13 -> 79.25 | EU13: =DL13 -> 82.4 | EV13: =DP13 -> 86.32 | EW13: =DT13 -> 84.52 | EX13: =DV13 -> 79.5 | EY13: =DX13 -> 89 | EZ13: =DZ13 -> 88.5 | FA13: =ED13 -> 84.888889 | FB13: =EH13 -> 85.233333 | FC13: =EI13 -> 82 | FD13: =EM13 -> 84.866667 | FE13: =AVERAGE(EN13:FD13) -> 84.232288
A14: 10 | B14: 0072799712 | C14: RASYA JULIAN SAPUTRA | D14: 12 TAV | E14: 86 | F14: 89 | G14: 89 | H14: 86 | I14: 90 | J14: 78 | K14: 84 | L14: 80 | M14: 92 | N14: 92 | O14: 92 | P14: 79 | Q14: 83 | R14: 77 | S14: 81 | T14: 79 | U14: 76 | V14: 77 | W14: 82 | X14: 84 | Y14: 82 | Z14: 84 | AA14: 89 | AB14: 86 | AC14: 73 | AD14: 80 | AE14: 87 | AF14: 92 | AG14: 87 | AH14: 85 | AI14: 74 | AJ14: 83 | AK14: 80 | AL14: 77 | AM14: 80 | AN14: 80 | AO14: 79 | AP14: 80 | AQ14: 81 | AR14: 78 | AS14: 77 | AT14: 83 | AU14: 80 | AV14: 75 | AW14: 86 | AX14: 78 | AY14: 75 | AZ14: 79 | BA14: 86 | BB14: 88 | BC14: 90 | BD14: 88 | BE14: 87 | BF14: 82 | BG14: 88 | BH14: 83 | BI14: 84 | BJ14: 85 | BK14: 86 | BL14: 78 | BM14: 80 | BN14: 78 | BO14: 86 | BP14: 78 | BQ14: 84 | BR14: 78 | BS14: =AVERAGE(BE14,BG14,BI14) -> 86.333333 | BT14: =AVERAGE(BF14,BH14,BJ14) -> 83.333333 | BU14: =AVERAGE(BK14,BM14,BO14,BQ14) -> 84 | BV14: =AVERAGE(BL14,BN14,BP14,BR14) -> 78 | BW14: 85 | BX14: 80 | BY14: 86 | BZ14: 79 | CA14: 78 | CB14: 80 | CC14: 86 | CD14: 74 | CE14: 78 | CF14: 82 | CG14: 92 | CH14: 75 | CI14: 82 | CJ14: 82 | CK14: 85 | CL14: 88 | CM14: 89 | CN14: 72 | CO14: =AVERAGE(E14:I14) -> 88 | CP14: =J14 -> 78 | CQ14: =CF14 -> 82 | CR14: =(CO14*4+CP14*3+CQ14*3)/10 -> 83.2 | CS14: =AVERAGE(K14:O14) -> 88 | CT14: =P14 -> 79 | CU14: =CG14 -> 92 | CV14: =(CS14*4+CT14*3+CU14*3)/10 -> 86.5 | CW14: =AVERAGE(Q14:U14) -> 79.2 | CX14: =V14 -> 77 | CY14: =CH14 -> 75 | CZ14: =(CW14*4+CX14*3+CY14*3)/10 -> 77.28 | DA14: =AVERAGE(W14:Z14) -> 83 | DB14: =DA14 -> 83 | DC14: =AVERAGE(AA14:AD14) -> 82 | DD14: =DC14 -> 82 | DE14: =AVERAGE(AE14:AF14) -> 89.5 | DF14: =DE14 -> 89.5 | DG14: =AVERAGE(AG14:AJ14) -> 82.25 | DH14: =DG14 -> 82.25 | DI14: =AK14 -> 80 | DJ14: =AL14 -> 77 | DK14: =CI14 -> 82 | DL14: =(DI14*4+DJ14*3+DK14*3)/10 -> 79.7 | DM14: =AVERAGE(AM14:AQ14) -> 80 | DN14: =AR14 -> 78 | DO14: =CJ14 -> 82 | DP14: =(DM14*4+DN14*3+DO14*3)/10 -> 80 | DQ14: =AVERAGE(AS14:AW14) -> 80.2 | DR14: =AX14 -> 78 | DS14: =CK14 -> 85 | DT14: =(DQ14*4+DR14*3+DS14*3)/10 -> 80.98 | DU14: =AVERAGE(AY14:AZ14) -> 77 | DV14: =DU14 -> 77 | DW14: =AVERAGE(BA14:BB14) -> 87 | DX14: =DW14 -> 87 | DY14: =AVERAGE(BC14:BD14) -> 89 | DZ14: =DY14 -> 89 | EA14: =AVERAGE(BS14:BU14) -> 84.555556 | EB14: =BV14 -> 78 | EC14: =CN14 -> 72 | ED14: =(EA14*4+EB14*3+EC14*3)/10 -> 78.822222 | EE14: =AVERAGE(BW14:BY14) -> 83.666667 | EF14: =BZ14 -> 79 | EG14: =CM14 -> 89 | EH14: =(EE14*4+EF14*3+EG14*3)/10 -> 83.866667 | EI14: =CA14 -> 78 | EJ14: =AVERAGE(CB14:CD14) -> 80 | EK14: =CE14 -> 78 | EL14: =CL14 -> 88 | EM14: =(EJ14*4+EK14*3+EL14*3)/10 -> 81.8 | EN14: =CR14 -> 83.2 | EO14: =CV14 -> 86.5 | EP14: =CZ14 -> 77.28 | EQ14: =DB14 -> 83 | ER14: =DD14 -> 82 | ES14: =DF14 -> 89.5 | ET14: =DH14 -> 82.25 | EU14: =DL14 -> 79.7 | EV14: =DP14 -> 80 | EW14: =DT14 -> 80.98 | EX14: =DV14 -> 77 | EY14: =DX14 -> 87 | EZ14: =DZ14 -> 89 | FA14: =ED14 -> 78.822222 | FB14: =EH14 -> 83.866667 | FC14: =EI14 -> 78 | FD14: =EM14 -> 81.8 | FE14: =AVERAGE(EN14:FD14) -> 82.346993
A15: 11 | B15: 0071406334 | C15: RAYHAN ADI SAPUTRA | D15: 12 TAV | E15: 82 | F15: 87 | G15: 86 | H15: 85 | I15: 84 | J15: 79 | K15: 80 | L15: 80 | M15: 88 | N15: 83 | O15: 88 | P15: 79 | Q15: 82 | R15: 80 | S15: 77 | T15: 72 | U15: 77 | V15: 79 | W15: 82 | X15: 85 | Y15: 84 | Z15: 85 | AA15: 81 | AB15: 84 | AC15: 73 | AD15: 78 | AE15: 83 | AF15: 84 | AG15: 83 | AH15: 85 | AI15: 70 | AJ15: 81 | AK15: 80 | AL15: 79 | AM15: 76 | AN15: 76 | AO15: 73 | AP15: 74 | AQ15: 79 | AR15: 80 | AS15: 72 | AT15: 77 | AU15: 75 | AV15: 73 | AW15: 83 | AX15: 80 | AY15: 75 | AZ15: 79 | BA15: 82 | BB15: 86 | BC15: 79 | BD15: 86 | BE15: 83 | BF15: 77 | BG15: 84 | BH15: 82 | BI15: 80 | BJ15: 84 | BK15: 82 | BL15: 80 | BM15: 80 | BN15: 80 | BO15: 86 | BP15: 80 | BQ15: 84 | BR15: 80 | BS15: =AVERAGE(BE15,BG15,BI15) -> 82.333333 | BT15: =AVERAGE(BF15,BH15,BJ15) -> 81 | BU15: =AVERAGE(BK15,BM15,BO15,BQ15) -> 83 | BV15: =AVERAGE(BL15,BN15,BP15,BR15) -> 80 | BW15: 85 | BX15: 80 | BY15: 85 | BZ15: 81 | CA15: 80 | CB15: 74 | CC15: 78 | CD15: 74 | CE15: 80 | CF15: 85 | CG15: 90 | CH15: 75 | CI15: 80 | CJ15: 80 | CK15: 83 | CL15: 85 | CM15: 97 | CN15: 70 | CO15: =AVERAGE(E15:I15) -> 84.8 | CP15: =J15 -> 79 | CQ15: =CF15 -> 85 | CR15: =(CO15*4+CP15*3+CQ15*3)/10 -> 83.12 | CS15: =AVERAGE(K15:O15) -> 83.8 | CT15: =P15 -> 79 | CU15: =CG15 -> 90 | CV15: =(CS15*4+CT15*3+CU15*3)/10 -> 84.22 | CW15: =AVERAGE(Q15:U15) -> 77.6 | CX15: =V15 -> 79 | CY15: =CH15 -> 75 | CZ15: =(CW15*4+CX15*3+CY15*3)/10 -> 77.24 | DA15: =AVERAGE(W15:Z15) -> 84 | DB15: =DA15 -> 84 | DC15: =AVERAGE(AA15:AD15) -> 79 | DD15: =DC15 -> 79 | DE15: =AVERAGE(AE15:AF15) -> 83.5 | DF15: =DE15 -> 83.5 | DG15: =AVERAGE(AG15:AJ15) -> 79.75 | DH15: =DG15 -> 79.75 | DI15: =AK15 -> 80 | DJ15: =AL15 -> 79 | DK15: =CI15 -> 80 | DL15: =(DI15*4+DJ15*3+DK15*3)/10 -> 79.7 | DM15: =AVERAGE(AM15:AQ15) -> 75.6 | DN15: =AR15 -> 80 | DO15: =CJ15 -> 80 | DP15: =(DM15*4+DN15*3+DO15*3)/10 -> 78.24 | DQ15: =AVERAGE(AS15:AW15) -> 76 | DR15: =AX15 -> 80 | DS15: =CK15 -> 83 | DT15: =(DQ15*4+DR15*3+DS15*3)/10 -> 79.3 | DU15: =AVERAGE(AY15:AZ15) -> 77 | DV15: =DU15 -> 77 | DW15: =AVERAGE(BA15:BB15) -> 84 | DX15: =DW15 -> 84 | DY15: =AVERAGE(BC15:BD15) -> 82.5 | DZ15: =DY15 -> 82.5 | EA15: =AVERAGE(BS15:BU15) -> 82.111111 | EB15: =BV15 -> 80 | EC15: =CN15 -> 70 | ED15: =(EA15*4+EB15*3+EC15*3)/10 -> 77.844444 | EE15: =AVERAGE(BW15:BY15) -> 83.333333 | EF15: =BZ15 -> 81 | EG15: =CM15 -> 97 | EH15: =(EE15*4+EF15*3+EG15*3)/10 -> 86.733333 | EI15: =CA15 -> 80 | EJ15: =AVERAGE(CB15:CD15) -> 75.333333 | EK15: =CE15 -> 80 | EL15: =CL15 -> 85 | EM15: =(EJ15*4+EK15*3+EL15*3)/10 -> 79.633333 | EN15: =CR15 -> 83.12 | EO15: =CV15 -> 84.22 | EP15: =CZ15 -> 77.24 | EQ15: =DB15 -> 84 | ER15: =DD15 -> 79 | ES15: =DF15 -> 83.5 | ET15: =DH15 -> 79.75 | EU15: =DL15 -> 79.7 | EV15: =DP15 -> 78.24 | EW15: =DT15 -> 79.3 | EX15: =DV15 -> 77 | EY15: =DX15 -> 84 | EZ15: =DZ15 -> 82.5 | FA15: =ED15 -> 77.844444 | FB15: =EH15 -> 86.733333 | FC15: =EI15 -> 80 | FD15: =EM15 -> 79.633333 | FE15: =AVERAGE(EN15:FD15) -> 80.928301
A16: 12 | B16: 0051828635 | C16: SELVIA OKTAVIANI | D16: 12 TAV | E16: 88 | F16: 90 | G16: 88 | H16: 88 | I16: 91 | J16: 75 | K16: 86 | L16: 80 | M16: 81 | N16: 88 | O16: 88 | P16: 70 | Q16: 85 | R16: 79 | S16: 81 | T16: 78 | U16: 77 | V16: 79 | W16: 82 | X16: 85 | Y16: 82 | Z16: 83 | AA16: 80 | AB16: 82 | AC16: 85 | AD16: 86 | AE16: 85 | AF16: 86 | AG16: 85 | AH16: 87 | AI16: 80 | AJ16: 82 | AK16: 84 | AL16: 79 | AM16: 75 | AN16: 77 | AO16: 77 | AP16: 78 | AQ16: 82 | AR16: 75 | AS16: 77 | AT16: 80 | AU16: 74 | AV16: 75 | AW16: 77 | AX16: 75 | AY16: 78 | AZ16: 79 | BA16: 82 | BB16: 82 | BC16: 91 | BD16: 80 | BE16: 81 | BF16: 76 | BG16: 82 | BH16: 81 | BI16: 82 | BJ16: 85 | BK16: 80 | BL16: 76 | BM16: 80 | BN16: 76 | BO16: 86 | BP16: 76 | BQ16: 84 | BR16: 76 | BS16: =AVERAGE(BE16,BG16,BI16) -> 81.666667 | BT16: =AVERAGE(BF16,BH16,BJ16) -> 80.666667 | BU16: =AVERAGE(BK16,BM16,BO16,BQ16) -> 82.5 | BV16: =AVERAGE(BL16,BN16,BP16,BR16) -> 76 | BW16: 84 | BX16: 81 | BY16: 86 | BZ16: 80 | CA16: 76 | CB16: 78 | CC16: 91 | CD16: 74 | CE16: 75 | CF16: 85 | CG16: 90 | CH16: 85 | CI16: 77 | CJ16: 83 | CK16: 85 | CL16: 89 | CM16: 91 | CN16: 85 | CO16: =AVERAGE(E16:I16) -> 89 | CP16: =J16 -> 75 | CQ16: =CF16 -> 85 | CR16: =(CO16*4+CP16*3+CQ16*3)/10 -> 83.6 | CS16: =AVERAGE(K16:O16) -> 84.6 | CT16: =P16 -> 70 | CU16: =CG16 -> 90 | CV16: =(CS16*4+CT16*3+CU16*3)/10 -> 81.84 | CW16: =AVERAGE(Q16:U16) -> 80 | CX16: =V16 -> 79 | CY16: =CH16 -> 85 | CZ16: =(CW16*4+CX16*3+CY16*3)/10 -> 81.2 | DA16: =AVERAGE(W16:Z16) -> 83 | DB16: =DA16 -> 83 | DC16: =AVERAGE(AA16:AD16) -> 83.25 | DD16: =DC16 -> 83.25 | DE16: =AVERAGE(AE16:AF16) -> 85.5 | DF16: =DE16 -> 85.5 | DG16: =AVERAGE(AG16:AJ16) -> 83.5 | DH16: =DG16 -> 83.5 | DI16: =AK16 -> 84 | DJ16: =AL16 -> 79 | DK16: =CI16 -> 77 | DL16: =(DI16*4+DJ16*3+DK16*3)/10 -> 80.4 | DM16: =AVERAGE(AM16:AQ16) -> 77.8 | DN16: =AR16 -> 75 | DO16: =CJ16 -> 83 | DP16: =(DM16*4+DN16*3+DO16*3)/10 -> 78.52 | DQ16: =AVERAGE(AS16:AW16) -> 76.6 | DR16: =AX16 -> 75 | DS16: =CK16 -> 85 | DT16: =(DQ16*4+DR16*3+DS16*3)/10 -> 78.64 | DU16: =AVERAGE(AY16:AZ16) -> 78.5 | DV16: =DU16 -> 78.5 | DW16: =AVERAGE(BA16:BB16) -> 82 | DX16: =DW16 -> 82 | DY16: =AVERAGE(BC16:BD16) -> 85.5 | DZ16: =DY16 -> 85.5 | EA16: =AVERAGE(BS16:BU16) -> 81.611111 | EB16: =BV16 -> 76 | EC16: =CN16 -> 85 | ED16: =(EA16*4+EB16*3+EC16*3)/10 -> 80.944444 | EE16: =AVERAGE(BW16:BY16) -> 83.666667 | EF16: =BZ16 -> 80 | EG16: =CM16 -> 91 | EH16: =(EE16*4+EF16*3+EG16*3)/10 -> 84.766667 | EI16: =CA16 -> 76 | EJ16: =AVERAGE(CB16:CD16) -> 81 | EK16: =CE16 -> 75 | EL16: =CL16 -> 89 | EM16: =(EJ16*4+EK16*3+EL16*3)/10 -> 81.6 | EN16: =CR16 -> 83.6 | EO16: =CV16 -> 81.84 | EP16: =CZ16 -> 81.2 | EQ16: =DB16 -> 83 | ER16: =DD16 -> 83.25 | ES16: =DF16 -> 85.5 | ET16: =DH16 -> 83.5 | EU16: =DL16 -> 80.4 | EV16: =DP16 -> 78.52 | EW16: =DT16 -> 78.64 | EX16: =DV16 -> 78.5 | EY16: =DX16 -> 82 | EZ16: =DZ16 -> 85.5 | FA16: =ED16 -> 80.944444 | FB16: =EH16 -> 84.766667 | FC16: =EI16 -> 76 | FD16: =EM16 -> 81.6 | FE16: =AVERAGE(EN16:FD16) -> 81.69183
... A18: 14 | B18: 0061447141 | C18: ZASKIA ZANIAR | D18: 12 TAV | E18: 88 | F18: 90 | G18: 89 | H18: 89 | I18: 91 | J18: 95 | K18: 85 | L18: 85 | M18: 95 | N18: 95 | O18: 95 | P18: 89 | Q18: 90 | R18: 85 | S18: 80 | T18: 87 | U18: 88 | V18: 87 | W18: 86 | X18: 86 | Y18: 85 | Z18: 86 | AA18: 83 | AB18: 88 | AC18: 86 | AD18: 87 | AE18: 85 | AF18: 87 | AG18: 85 | AH18: 89 | AI18: 73 | AJ18: 82 | AK18: 90 | AL18: 87 | AM18: 75 | AN18: 77 | AO18: 75 | AP18: 76 | AQ18: 81 | AR18: 86 | AS18: 93 | AT18: 90 | AU18: 87 | AV18: 83 | AW18: 86 | AX18: 86 | AY18: 79 | AZ18: 80 | BA18: 88 | BB18: 95 | BC18: 91 | BD18: 83 | BE18: 86 | BF18: 80 | BG18: 88 | BH18: 83 | BI18: 84 | BJ18: 86 | BK18: 86 | BL18: 89 | BM18: 80 | BN18: 89 | BO18: 86 | BP18: 89 | BQ18: 85 | BR18: 89 | BS18: =AVERAGE(BE18,BG18,BI18) -> 86 | BT18: =AVERAGE(BF18,BH18,BJ18) -> 83 | BU18: =AVERAGE(BK18,BM18,BO18,BQ18) -> 84.25 | BV18: =AVERAGE(BL18,BN18,BP18,BR18) -> 89 | BW18: 85 | BX18: 82 | BY18: 86 | BZ18: 86 | CA18: 89 | CB18: 84 | CC18: 92 | CD18: 85 | CE18: 86 | CF18: 91 | CG18: 95 | CH18: 85 | CI18: 97 | CJ18: 82 | CK18: 86 | CL18: 89 | CM18: 97 | CN18: 75 | CO18: =AVERAGE(E18:I18) -> 89.4 | CP18: =J18 -> 95 | CQ18: =CF18 -> 91 | CR18: =(CO18*4+CP18*3+CQ18*3)/10 -> 91.56 | CS18: =AVERAGE(K18:O18) -> 91 | CT18: =P18 -> 89 | CU18: =CG18 -> 95 | CV18: =(CS18*4+CT18*3+CU18*3)/10 -> 91.6 | CW18: =AVERAGE(Q18:U18) -> 86 | CX18: =V18 -> 87 | CY18: =CH18 -> 85 | CZ18: =(CW18*4+CX18*3+CY18*3)/10 -> 86 | DA18: =AVERAGE(W18:Z18) -> 85.75 | DB18: =DA18 -> 85.75 | DC18: =AVERAGE(AA18:AD18) -> 86 | DD18: =DC18 -> 86 | DE18: =AVERAGE(AE18:AF18) -> 86 | DF18: =DE18 -> 86 | DG18: =AVERAGE(AG18:AJ18) -> 82.25 | DH18: =DG18 -> 82.25 | DI18: =AK18 -> 90 | DJ18: =AL18 -> 87 | DK18: =CI18 -> 97 | DL18: =(DI18*4+DJ18*3+DK18*3)/10 -> 91.2 | DM18: =AVERAGE(AM18:AQ18) -> 76.8 | DN18: =AR18 -> 86 | DO18: =CJ18 -> 82 | DP18: =(DM18*4+DN18*3+DO18*3)/10 -> 81.12 | DQ18: =AVERAGE(AS18:AW18) -> 87.8 | DR18: =AX18 -> 86 | DS18: =CK18 -> 86 | DT18: =(DQ18*4+DR18*3+DS18*3)/10 -> 86.72 | DU18: =AVERAGE(AY18:AZ18) -> 79.5 | DV18: =DU18 -> 79.5 | DW18: =AVERAGE(BA18:BB18) -> 91.5 | DX18: =DW18 -> 91.5 | DY18: =AVERAGE(BC18:BD18) -> 87 | DZ18: =DY18 -> 87 | EA18: =AVERAGE(BS18:BU18) -> 84.416667 | EB18: =BV18 -> 89 | EC18: =CN18 -> 75 | ED18: =(EA18*4+EB18*3+EC18*3)/10 -> 82.966667 | EE18: =AVERAGE(BW18:BY18) -> 84.333333 | EF18: =BZ18 -> 86 | EG18: =CM18 -> 97 | EH18: =(EE18*4+EF18*3+EG18*3)/10 -> 88.633333 | EI18: =CA18 -> 89 | EJ18: =AVERAGE(CB18:CD18) -> 87 | EK18: =CE18 -> 86 | EL18: =CL18 -> 89 | EM18: =(EJ18*4+EK18*3+EL18*3)/10 -> 87.3 | EN18: =CR18 -> 91.56 | EO18: =CV18 -> 91.6 | EP18: =CZ18 -> 86 | EQ18: =DB18 -> 85.75 | ER18: =DD18 -> 86 | ES18: =DF18 -> 86 | ET18: =DH18 -> 82.25 | EU18: =DL18 -> 91.2 | EV18: =DP18 -> 81.12 | EW18: =DT18 -> 86.72 | EX18: =DV18 -> 79.5 | EY18: =DX18 -> 91.5 | EZ18: =DZ18 -> 87 | FA18: =ED18 -> 82.966667 | FB18: =EH18 -> 88.633333 | FC18: =EI18 -> 89 | FD18: =EM18 -> 87.3 | FE18: =AVERAGE(EN18:FD18) -> 86.711765

Sheet Sheet2
B3: LAPORAN MASING - MASING WALAS XII | H3: XII TKJ 2 | I3: Fatmawaty | M3: XII AK | N3: Heni
H4: L | I4: 18 | M4: L | N4: 0
B5: XII TE | C5: halim hafis | H5: P | I5: 17 | M5: P | N5: 40
B6: L | C6: 8 | H6: JUMLAH SISWA | I6: 35 | M6: JUMLAH SISWA | N6: 40
B7: P | C7: 6 | H7: SISWA YG BERMASALAH | K7: DITA ROSALINDA | M7: SISWA YG BERMASALAH
B8: JUMLAH SISWA | C8: 14 | K8: ABSENSI
B9: siswa bermasalah | C9: Jericho | D9: ABSENSI
C10: Khalip | D10: ABSENSI
B13: XII TO 1 | C13: HERLAMBANG PRAMONO, S.Pd
B14: L | C14: 20 | H14: XII TKJ 3 | I14: Listia
B15: P | C15: 0 | H15: L | I15: 17
B16: JUMLAH SISWA | C16: 20 | H16: P | I16: 19
B17: SISWA YG BERMASALAH | D17: IHSANTOSO | H17: JUMLAH SISWA | I17: 36
D18: ABSENSI | H18: SISWA YG BERMASALAH | K18: M. Nizar
K19: ABSENSI
B20: XII TO 2 | C20: NURAINI, S.Pd
B21: L | C21: 19
B22: P | C22: 0
B23: JUMLAH SISWA | C23: 19
B24: SISWA YG BERMASALAH | D24: ALGHANIYYU
D25: ABSENSI
B27: XII TKJ 1 | C27: WAHYU PERDANA, S.Kom
B28: L | C28: 15
B29: P | C29: 21
B30: JUMLAH | C30: 36
B31: SISWA BERMASALAH

Sheet SISWA PRESTASI
A1: NO | B1: NAMA | C1: KLS | D1: NS
A2: 175 | B2: ELISYA MEIZAHRA | C2: 12 AKL | D2: 88.901765 | G2: NAMA SISWA PRESTASI BID. AKADEMIK | H2: KELAS | I2: RATA2 NILAI AKHIR SEKOLAH | J2: KET
A3: 178 | B3: HALUNA SHAFA RAHMADANI | C3: 12 AKL | D3: 88.86549 | G3: ELISYA MEIZAHRA | H3: 12 AKL | I3: 88.901765
A4: 143 | B4: MUHAMMAD RIFKI HIDAYAT | C4: 12 TKJ 3 | D4: 88.441307 | G4: MUHAMMAD RIFKI HIDAYAT | H4: 12 TKJ 3 | I4: 88.441307
A5: 62 | B5: B'RIEW ONGARTA KAYANA | C5: 12 TKJ 1 | D5: 88.107712 | G5: RASYA FIRMANSAH | H5: 12 TKR 1 | I5: 87.944771
A6: 95 | B6: BILQIS NAZWA SAFIRA | C6: 12 TKJ 2 | D6: 88.062222 | G6: ZASKIA ZANIAR | H6: 12 TAV | I6: 86.711765
A7: 33 | B7: RASYA FIRMANSAH | C7: 12 TKR 1 | D7: 87.944771
A8: 192 | B8: RENDA MAWAR RANI | C8: 12 AKL | D8: 87.909804
A9: 43 | B9: MOCH FAUZAN FIRDAUS | C9: 12 TKR 2 | D9: 87.696667
A10: 60 | B10: AY GRACE JIREHANAFI | C10: 12 TKJ 1 | D10: 87.204837
A11: 118 | B11: RETNO PUTRI AMELIA | C11: 12 TKJ 2 | D11: 87.14634
A12: 181 | B12: MEVIA ANDARA ARIF | C12: 12 AKL | D12: 87.142353
A13: 125 | B13: AHMAD RAMDANI | C13: 12 TKJ 3 | D13: 86.805752
A14: 120 | B14: SALMA TIANA | C14: 12 TKJ 2 | D14: 86.790458
A15: 14 | B15: ZASKIA ZANIAR | C15: 12 TAV | D15: 86.711765
A16: 124 | B16: ZAHRA MAULIDAH | C16: 12 TKJ 2 | D16: 86.653595
A17: 102 | B17: HALIM DAFA ANDIKA | C17: 12 TKJ 2 | D17: 86.501176
A18: 189 | B18: R. CAYSHIA FEBRILYAN | C18: 12 AKL | D18: 86.445686
... A201: 36 | B201: AL GHANIYYU SYAHRUL PARINDINGAN | C201: 12 TKR 2 | D201: 77.500392

Sheet 12 TE
A1: PENGOLAHAN NILAI UJIAN SATUAN PENDIDIKAN
A2: TAHUN PELAJARAN 2024 / 2025
A4: NAMA SEKOLAH | D4: : SMKS TINTA EMAS INDONESIA
A5: ALAMAT | D5: : JL. ASEM RAYA NO.1 KP. CIKETING KEL./KEC. MUSTIKA JAYA KOTA BEKASI 17158
A8: NOMOR | B8: NIS | C8: NAMA SISWA | E8: MATA PELAJARAN UMUM | K8: MUATAN LOKAL | M8: MATA PELAJARAN KEJURUAN | V8: NILAI RATA-RATA
D9: JENIS NILAI | E9: Pend. Agama dan Budi Pekerti | F9: PendIdikan Pancasila | G9: Bahasa Indonesia | H9: Pendidikan Jasmani, Olah Raga dan Kesehatan | I9: Sejarah | J9: Seni Budaya | K9: Bahasa Sunda | L9: Publik Speaking | M9: Matematika | N9: Bahasa Inggris | O9: Informatika | P9: IPAS | Q9: Dasar-Dasar Program Keahlian | R9: Konsentrasi Keahlian | S9: Projek Kreatif dan Kewirausahaan | T9: Praktek Kerja Lapangan | U9: Mata Pelajaran Pilihan (Bahasa Jepang)
AB10: 49
AB11: 12
A12: 1 | B12: 222310001 | C12: ADRIAN FAUZAN | D12: SMT 1 | E12: =te!$E$5 -> 82 | F12: =te!$K$5 -> 80 | G12: =te!$Q$5 -> 80 | H12: =te!$W$5 -> 82 | I12: =te!$AA$5 -> 75 | J12: =te!$AE$5 -> 83 | K12: =te!$AG$5 -> 83 | M12: =te!$AM$5 -> 75 | N12: =te!$AS$5 -> 73 | O12: =te!$AY$5 -> 75 | P12: =te!$BA$5 -> 79 | Q12: =te!$BC$5 -> 85 | X12: 5 | AB12: 44
D13: SMT 2 | E13: =te!$F$5 -> 89 | F13: =te!$L$5 -> 81 | G13: =te!$R$5 -> 77 | H13: =te!$X$5 -> 83 | I13: =te!$AB$5 -> 78 | J13: =te!$AF$5 -> 83 | K13: =te!$AH$5 -> 85 | M13: =te!$AN$5 -> 76 | N13: =te!$AT$5 -> 73 | O13: =te!$AZ$5 -> 80 | P13: =te!$BB$5 -> 80 | Q13: =te!$BD$5 -> 75 | X13: 5 | AB13: 34
D14: SMT 3 | E14: =te!$G$5 -> 86 | F14: =te!$M$5 -> 70 | G14: =te!$S$5 -> 70 | H14: =te!$Y$5 -> 80 | I14: =te!$AC$5 -> 73 | K14: =te!$AI$5 -> 70 | M14: =te!$AO$5 -> 72 | N14: =te!$AU$5 -> 71 | R14: =te!$BS$5 -> 75.666667 | S14: =te!$BW$5 -> 82 | U14: =te!$CB$5 -> 70 | X14: 5 | AB14: 33
D15: SMT 4 | E15: =te!$H$5 -> 85 | F15: =te!$N$5 -> 83 | G15: =te!$T$5 -> 72 | H15: =te!$Z$5 -> 83 | I15: =te!$AD$5 -> 75 | K15: =te!$AJ$5 -> 80 | M15: =te!$AP$5 -> 73 | N15: =te!$AV$5 -> 70 | R15: =te!$BT$5 -> 79.333333 | S15: =te!$BX$5 -> 80 | U15: =te!$CC$5 -> 72 | X15: 5 | AB15: 42
D16: SMT 5 | E16: =te!$I$5 -> 80 | F16: =te!$O$5 -> 88 | G16: =te!$U$5 -> 73 | L16: =te!$AK$5 -> 89 | M16: =te!$AQ$5 -> 76 | N16: =te!$AW$5 -> 73 | R16: =te!$BU$5 -> 77 | S16: =te!$BY$5 -> 70 | U16: =te!$CD$5 -> 74 | X16: 5 | AB16: 43
D17: PORTOPOLIO | E17: =AVERAGE(E12:E16) -> 84.4 | F17: =AVERAGE(F12:F16) -> 80.4 | G17: =AVERAGE(G12:G16) -> 74.4 | L17: =AVERAGE(L12:L16) -> 89 | M17: =AVERAGE(M12:M16) -> 74.4 | N17: =AVERAGE(N12:N16) -> 72 | R17: =AVERAGE(R14:R16) -> 77.333333 | S17: =AVERAGE(S14:S16) -> 77.333333 | U17: =AVERAGE(U12:U16) -> 72 | X17: 5 | AB17: 29
D18: PENUGASAN | E18: =te!$J$5 -> 80 | F18: =te!$P$5 -> 81 | G18: =te!$V$5 -> 78 | L18: =te!$AL$5 -> 78 | M18: =te!$AR$5 -> 80 | N18: =te!$AX$5 -> 80 | R18: =te!$BV$5 -> 80 | S18: =te!$BZ$5 -> 79 | T18: =te!$CA$5 -> 80 | U18: =te!$CE$5 -> 80 | X18: 5 | AB18: 58
D19: Nilai US | E19: =te!$CF$5 -> 81 | F19: =te!$CG$5 -> 75 | G19: =te!$CH$5 -> 75 | L19: =te!$CI$5 -> 75 | M19: =te!$CJ$5 -> 76 | N19: =te!$CK$5 -> 80 | R19: =te!$CN$5 -> 70 | S19: =te!$CM$5 -> 71 | U19: =te!$CL$5 -> 70 | X19: 5 | AB19: 34
D20: Nilai Akhir | E20: =(E17*4+E18*3+E19*3)/10 -> 82.06 | F20: =(F17*4+F18*3+F19*3)/10 -> 78.96 | G20: =(G17*4+G18*3+G19*3)/10 -> 75.66 | H20: =AVERAGE(H12:H15) -> 82 | I20: =AVERAGE(I12:I15) -> 75.25 | J20: =AVERAGE(J12:J13) -> 83 | K20: =AVERAGE(K12:K15) -> 79.5 | L20: =(L17*4+L18*3+L19*3)/10 -> 81.5 | M20: =(M17*4+M18*3+M19*3)/10 -> 76.56 | N20: =(N17*4+N18*3+N19*3)/10 -> 76.8 | O20: =AVERAGE(O12:O13) -> 77.5 | P20: =AVERAGE(P12:P13) -> 79.5 | Q20: =AVERAGE(Q12:Q13) -> 80 | R20: =(R17*4+R18*3+R19*3)/10 -> 75.933333 | S20: =(S17*4+S18*3+S19*3)/10 -> 75.933333 | T20: =T18 -> 80 | U20: =(U17*4+U18*3+U19*3)/10 -> 73.8 | V20: =AVERAGE(E20:U20) -> 78.468039 | X20: 5 | AB20: 32
A21: 2 | B21: 222310002 | C21: AHMAD ZAKI YAMAN | D21: SMT 1 | E21: =te!$E$6 -> 82 | F21: =te!$K$6 -> 80 | G21: =te!$Q$6 -> 80 | H21: =te!$W$6 -> 80 | I21: =te!$AA$6 -> 75 | J21: =te!$AE$6 -> 83 | K21: =te!$AG$6 -> 83 | M21: =te!$AM$6 -> 73 | N21: =te!$AS$6 -> 72 | O21: =te!$AY$6 -> 74 | P21: =te!$BA$6 -> 78 | Q21: =te!$BC$6 -> 90 | X21: 6 | AB21: 14
A22: 2 | D22: SMT 2 | E22: =te!$F$6 -> 88 | F22: =te!$L$6 -> 81 | G22: =te!$R$6 -> 77 | H22: =te!$X$6 -> 83 | I22: =te!$AB$6 -> 78 | J22: =te!$AF$6 -> 83 | K22: =te!$AH$6 -> 84 | M22: =te!$AN$6 -> 74 | N22: =te!$AT$6 -> 74 | O22: =te!$AZ$6 -> 79 | P22: =te!$BB$6 -> 81 | Q22: =te!$BD$6 -> 77 | X22: 6
A23: 2 | D23: SMT 3 | E23: =te!$G$6 -> 87 | F23: =te!$M$6 -> 70 | G23: =te!$S$6 -> 70 | H23: =te!$Y$6 -> 80 | I23: =te!$AC$6 -> 80 | K23: =te!$AI$6 -> 70 | M23: =te!$AO$6 -> 73 | N23: =te!$AU$6 -> 72 | R23: =te!$BS$6 -> 74.666667 | S23: =te!$BW$6 -> 82 | U23: =te!$CB$6 -> 72 | X23: 6
A24: 2 | D24: SMT 4 | E24: =te!$H$6 -> 85 | F24: =te!$N$6 -> 83 | G24: =te!$T$6 -> 73 | H24: =te!$Z$6 -> 83 | I24: =te!$AD$6 -> 80 | K24: =te!$AJ$6 -> 80 | M24: =te!$AP$6 -> 74 | N24: =te!$AV$6 -> 70 | R24: =te!$BT$6 -> 78 | S24: =te!$BX$6 -> 80 | U24: =te!$CC$6 -> 74 | X24: 6
A25: 2 | D25: SMT 5 | E25: =te!$I$6 -> 84 | F25: =te!$O$6 -> 88 | G25: =te!$U$6 -> 75 | L25: =te!$AK$6 -> 80 | M25: =te!$AQ$6 -> 75 | N25: =te!$AW$6 -> 77 | R25: =te!$BU$6 -> 79 | S25: =te!$BY$6 -> 70 | U25: =te!$CD$6 -> 74 | X25: 6
A26: 2 | D26: PORTOPOLIO | E26: =AVERAGE(E21:E25) -> 85.2 | F26: =AVERAGE(F21:F25) -> 80.4 | G26: =AVERAGE(G21:G25) -> 75 | L26: =AVERAGE(L21:L25) -> 80 | M26: =AVERAGE(M21:M25) -> 73.8 | N26: =AVERAGE(N21:N25) -> 73 | R26: =AVERAGE(R23:R25) -> 77.222222 | S26: =AVERAGE(S23:S25) -> 77.333333 | U26: =AVERAGE(U21:U25) -> 73.333333 | X26: 6
A27: 2 | D27: PENUGASAN | E27: =te!$J$6 -> 76 | F27: =te!$P$6 -> 78 | G27: =te!$V$6 -> 78 | L27: =te!$AL$6 -> 78 | M27: =te!$AR$6 -> 77 | N27: =te!$AX$6 -> 77 | R27: =te!$BV$6 -> 78 | S27: =te!$BZ$6 -> 79 | T27: =te!$CA$6 -> 78 | U27: =te!$CE$6 -> 77 | X27: 6
A28: 2 | D28: Nilai US | E28: =te!$CF$6 -> 84 | F28: =te!$CG$6 -> 75 | G28: =te!$CH$6 -> 75 | L28: =te!$CI$6 -> 70 | M28: =te!$CJ$6 -> 76 | N28: =te!$CK$6 -> 80 | R28: =te!$CN$6 -> 70 | S28: =te!$CM$6 -> 73 | U28: =te!$CL$6 -> 72 | X28: 6
A29: 2 | D29: Nilai Akhir | E29: =(E26*4+E27*3+E28*3)/10 -> 82.08 | F29: =(F26*4+F27*3+F28*3)/10 -> 78.06 | G29: =(G26*4+G27*3+G28*3)/10 -> 75.9 | H29: =AVERAGE(H21:H24) -> 81.5 | I29: =AVERAGE(I21:I24) -> 78.25 | J29: =AVERAGE(J21:J22) -> 83 | K29: =AVERAGE(K21:K24) -> 79.25 | L29: =(L26*4+L27*3+L28*3)/10 -> 76.4 | M29: =(M26*4+M27*3+M28*3)/10 -> 75.42 | N29: =(N26*4+N27*3+N28*3)/10 -> 76.3 | O29: =AVERAGE(O21:O22) -> 76.5 | P29: =AVERAGE(P21:P22) -> 79.5 | Q29: =AVERAGE(Q21:Q22) -> 83.5 | R29: =(R26*4+R27*3+R28*3)/10 -> 75.288889 | S29: =(S26*4+S27*3+S28*3)/10 -> 76.533333 | T29: =T27 -> 78 | U29: =(U26*4+U27*3+U28*3)/10 -> 74.033333 | V29: =AVERAGE(E29:U29) -> 78.206797 | X29: 6
A30: 3 | B30: 222310003 | C30: AMANDA ZAHRA FEBRIYANI | D30: SMT 1 | E30: =te!$E$7 -> 82 | F30: =te!$K$7 -> 81 | G30: =te!$Q$7 -> 85 | H30: =te!$W$7 -> 82 | I30: =te!$AA$7 -> 80 | J30: =te!$AE$7 -> 85 | K30: =te!$AG$7 -> 85 | M30: =te!$AM$7 -> 75 | N30: =te!$AS$7 -> 74 | O30: =te!$AY$7 -> 77 | P30: =te!$BA$7 -> 83 | Q30: =te!$BC$7 -> 80 | X30: 7
A31: 3 | D31: SMT 2 | E31: =te!$F$7 -> 87 | F31: =te!$L$7 -> 83 | G31: =te!$R$7 -> 80 | H31: =te!$X$7 -> 85 | I31: =te!$AB$7 -> 88 | J31: =te!$AF$7 -> 83 | K31: =te!$AH$7 -> 85 | M31: =te!$AN$7 -> 77 | N31: =te!$AT$7 -> 79 | O31: =te!$AZ$7 -> 81 | P31: =te!$BB$7 -> 82 | Q31: =te!$BD$7 -> 80 | X31: 7
A32: 3 | D32: SMT 3 | E32: =te!$G$7 -> 86 | F32: =te!$M$7 -> 83 | G32: =te!$S$7 -> 89 | H32: =te!$Y$7 -> 83 | I32: =te!$AC$7 -> 85 | K32: =te!$AI$7 -> 72 | M32: =te!$AO$7 -> 75 | N32: =te!$AU$7 -> 82 | R32: =te!$BS$7 -> 80 | S32: =te!$BW$7 -> 84 | U32: =te!$CB$7 -> 79 | X32: 7
A33: 3 | D33: SMT 4 | E33: =te!$H$7 -> 85 | F33: =te!$N$7 -> 88 | G33: =te!$T$7 -> 87 | H33: =te!$Z$7 -> 84 | I33: =te!$AD$7 -> 86 | K33: =te!$AJ$7 -> 81 | M33: =te!$AP$7 -> 76 | N33: =te!$AV$7 -> 74 | R33: =te!$BT$7 -> 81.333333 | S33: =te!$BX$7 -> 81 | U33: =te!$CC$7 -> 92 | X33: 7
A34: 3 | D34: SMT 5 | E34: =te!$I$7 -> 84 | F34: =te!$O$7 -> 93 | G34: =te!$U$7 -> 81 | L34: =te!$AK$7 -> 84 | M34: =te!$AQ$7 -> 82 | N34: =te!$AW$7 -> 85 | R34: =te!$BU$7 -> 82.75 | S34: =te!$BY$7 -> 86 | U34: =te!$CD$7 -> 89 | X34: 7
A35: 3 | D35: PORTOPOLIO | E35: =AVERAGE(E30:E34) -> 84.8 | F35: =AVERAGE(F30:F34) -> 85.6 | G35: =AVERAGE(G30:G34) -> 84.4 | L35: =AVERAGE(L30:L34) -> 84 | M35: =AVERAGE(M30:M34) -> 77 | N35: =AVERAGE(N30:N34) -> 78.8 | R35: =AVERAGE(R32:R34) -> 81.361111 | S35: =AVERAGE(S32:S34) -> 83.666667 | U35: =AVERAGE(U30:U34) -> 86.666667 | X35: 7
A36: 3 | D36: PENUGASAN | E36: =te!$J$7 -> 86 | F36: =te!$P$7 -> 95 | G36: =te!$V$7 -> 86 | L36: =te!$AL$7 -> 86 | M36: =te!$AR$7 -> 91 | N36: =te!$AX$7 -> 91 | R36: =te!$BV$7 -> 90 | S36: =te!$BZ$7 -> 90 | T36: =te!$CA$7 -> 90 | U36: =te!$CE$7 -> 91 | X36: 7
A37: 3 | D37: Nilai US | E37: =te!$CF$7 -> 86 | F37: =te!$CG$7 -> 85 | G37: =te!$CH$7 -> 82 | L37: =te!$CI$7 -> 95 | M37: =te!$CJ$7 -> 83 | N37: =te!$CK$7 -> 85 | R37: =te!$CN$7 -> 82 | S37: =te!$CM$7 -> 87 | U37: =te!$CL$7 -> 84 | X37: 7
A38: 3 | D38: Nilai Akhir | E38: =(E35*4+E36*3+E37*3)/10 -> 85.52 | F38: =(F35*4+F36*3+F37*3)/10 -> 88.24 | G38: =(G35*4+G36*3+G37*3)/10 -> 84.16 | H38: =AVERAGE(H30:H33) -> 83.5 | I38: =AVERAGE(I30:I33) -> 84.75 | J38: =AVERAGE(J30:J31) -> 84 | K38: =AVERAGE(K30:K33) -> 80.75 | L38: =(L35*4+L36*3+L37*3)/10 -> 87.9 | M38: =(M35*4+M36*3+M37*3)/10 -> 83 | N38: =(N35*4+N36*3+N37*3)/10 -> 84.32 | O38: =AVERAGE(O30:O31) -> 79 | P38: =AVERAGE(P30:P31) -> 82.5 | Q38: =AVERAGE(Q30:Q31) -> 80 | R38: =(R35*4+R36*3+R37*3)/10 -> 84.144444 | S38: =(S35*4+S36*3+S37*3)/10 -> 86.566667 | T38: =T36 -> 90 | U38: =(U35*4+U36*3+U37*3)/10 -> 87.166667 | V38: =AVERAGE(E38:U38) -> 84.442222 | X38: 7
A39: 4 | B39: 222310004 | C39: ANGGI ISMAYANTI | D39: SMT 1 | E39: =te!$E$8 -> 86 | F39: =te!$K$8 -> 83 | G39: =te!$Q$8 -> 87 | H39: =te!$W$8 -> 81 | I39: =te!$AA$8 -> 77 | J39: =te!$AE$8 -> 84 | K39: =te!$AG$8 -> 84 | M39: =te!$AM$8 -> 77 | N39: =te!$AS$8 -> 77 | O39: =te!$AY$8 -> 80 | P39: =te!$BA$8 -> 84 | Q39: =te!$BC$8 -> 83 | X39: 8
A40: 4 | D40: SMT 2 | E40: =te!$F$8 -> 90 | F40: =te!$L$8 -> 81 | G40: =te!$R$8 -> 80 | H40: =te!$X$8 -> 85 | I40: =te!$AB$8 -> 88 | J40: =te!$AF$8 -> 85 | K40: =te!$AH$8 -> 85 | M40: =te!$AN$8 -> 79 | N40: =te!$AT$8 -> 79 | O40: =te!$AZ$8 -> 82 | P40: =te!$BB$8 -> 85 | Q40: =te!$BD$8 -> 81 | X40: 8
A41: 4 | D41: SMT 3 | E41: =te!$G$8 -> 88 | F41: =te!$M$8 -> 82 | G41: =te!$S$8 -> 80 | H41: =te!$Y$8 -> 83 | I41: =te!$AC$8 -> 85 | K41: =te!$AI$8 -> 71 | M41: =te!$AO$8 -> 78 | N41: =te!$AU$8 -> 73 | R41: =te!$BS$8 -> 81.666667 | S41: =te!$BW$8 -> 84 | U41: =te!$CB$8 -> 78 | X41: 8
A42: 4 | D42: SMT 4 | E42: =te!$H$8 -> 87 | F42: =te!$N$8 -> 89 | G42: =te!$T$8 -> 80 | H42: =te!$Z$8 -> 84 | I42: =te!$AD$8 -> 86 | K42: =te!$AJ$8 -> 81 | M42: =te!$AP$8 -> 79 | N42: =te!$AV$8 -> 72 | R42: =te!$BT$8 -> 80 | S42: =te!$BX$8 -> 81 | U42: =te!$CC$8 -> 91 | X42: 8
A43: 4 | D43: SMT 5 | E43: =te!$I$8 -> 90 | F43: =te!$O$8 -> 89 | G43: =te!$U$8 -> 85 | L43: =te!$AK$8 -> 85 | M43: =te!$AQ$8 -> 82 | N43: =te!$AW$8 -> 82 | R43: =te!$BU$8 -> 82.5 | S43: =te!$BY$8 -> 86 | U43: =te!$CD$8 -> 74 | X43: 8
...

Sheet tkr
A1: NO | B1: NIS | C1: NAMA PESERTA | D1: KELAS | BC1: TEKNIK JARINGAN KOMPUTER DAN TELEKOMUNIKASI | BE1: MAPEL KONSENTRASI KEAHLIAN | BI1: MAPEL KONSENTRASI KEAHLIAN | BM1: MAPEL KONSENTRASI KEAHLIAN | CD1: NILAI UJIAN SEKOLAH | CM1: =E2 -> 1.Pendidikan Agama Islam (PAI) | CQ1: =K2 -> 2.Pendidikan Pancasila | CU1: =Q2 -> 3.Bahasa Indonesia | CY1: =W2 -> 4.Pendidikan Jasmani Olahraga dan Kesehatan | DA1: =AA2 -> 5.Sejarah | DC1: =AE2 -> 6.Seni Budaya (Seni Tari) | DE1: =AG2 -> 7.Bahasa Sunda | DG1: =AK2 -> 8.Public speaking | DK1: =AM2 -> 9.Matematika | DO1: =AS2 -> 10.Bahasa Inggris | DS1: =AY2 -> 11.Informatika | DU1: =BA2 -> 12.Projek Ilmu Pengetahuan Alam dan Sosial | DW1: =BC2 -> 13.Dasar - dasar Program Keahlian | DY1: 14. Konsentrasi Keahlian | EC1: =BU2 -> 15.Projek Kreatif dan Kewirausahaan | EG1: 16.PKL | EH1: =BZ2 -> 17.Bahasa Jepang | EL1: NILAI IJAZAH / SKL
E2: 1.Pendidikan Agama Islam (PAI) | K2: 2.Pendidikan Pancasila | Q2: 3.Bahasa Indonesia | W2: 4.Pendidikan Jasmani Olahraga dan Kesehatan | AA2: 5.Sejarah | AE2: 6.Seni Budaya (Seni Tari) | AG2: 7.Bahasa Sunda | AK2: 8.Public speaking | AM2: 9.Matematika | AS2: 10.Bahasa Inggris | AY2: 11.Informatika | BA2: 12.Projek Ilmu Pengetahuan Alam dan Sosial | BC2: 13.Dasar - dasar Program Keahlian | BE2: 14.Pemeliharaan Mesin Kendaraan Ringan | BI2: 14.Pemeliharaan Cassis & Pemindah Tenaga | BM2: 14.Pemeliharaan Kelistrikan Kendaraan Ringan | BQ2: KONS | BU2: 15.Projek Kreatif dan Kewirausahaan | BY2: 16.PKL | BZ2: 17.Bahasa Jepang | EL2: 1.Pendidikan Agama dan Budi Pekerti | EM2: 2.Pendidikan Pancasila | EN2: 3.Bahasa Indonesia | EO2: 4.Pendidikan Jasmani Olahraga dan Kesehatan | EP2: 5.Sejarah | EQ2: 6.Seni Budaya (Seni Tari) | ER2: 7.Bahasa Sunda | ES2: 8.Public speaking | ET2: 9.Matematika | EU2: 10.Bahasa Inggris | EV2: 11.Informatika | EW2: 12.Projek Ilmu Pengetahuan Alam dan Sosial | EX2: 13.Dasar - dasar Program Keahlian | EY2: 14.Konsentrasi Keahlian | EZ2: 15.Projek Kreatif dan Kewirausahaan | FA2: 16.Praktik Kerja Lapangan | FB2: 17.Mepel Pilihan (Bahasa Jepang) | FC2: RATA-RATA
